[2023-05-13T19:53:28.716+0000] {processor.py:153} INFO - Started process (PID=188) to work on /opt/airflow/dags/gw2_dag.py
[2023-05-13T19:53:28.716+0000] {processor.py:743} INFO - Processing file /opt/airflow/dags/gw2_dag.py for tasks to queue
[2023-05-13T19:53:28.717+0000] {logging_mixin.py:137} INFO - [2023-05-13T19:53:28.717+0000] {dagbag.py:538} INFO - Filling up the DagBag from /opt/airflow/dags/gw2_dag.py
[2023-05-13T19:53:28.752+0000] {logging_mixin.py:137} INFO - [2023-05-13T19:53:28.750+0000] {dagbag.py:343} ERROR - Failed to import: /opt/airflow/dags/gw2_dag.py
Traceback (most recent call last):
  File "/home/airflow/.local/lib/python3.7/site-packages/airflow/models/dagbag.py", line 339, in parse
    loader.exec_module(new_module)
  File "<frozen importlib._bootstrap_external>", line 728, in exec_module
  File "<frozen importlib._bootstrap>", line 219, in _call_with_frames_removed
  File "/opt/airflow/dags/gw2_dag.py", line 16, in <module>
    from src.url_writer import url_writer_script
ModuleNotFoundError: No module named 'src'
[2023-05-13T19:53:28.752+0000] {processor.py:755} WARNING - No viable dags retrieved from /opt/airflow/dags/gw2_dag.py
[2023-05-13T19:53:28.927+0000] {processor.py:175} INFO - Processing /opt/airflow/dags/gw2_dag.py took 0.214 seconds
[2023-05-13T19:53:59.720+0000] {processor.py:153} INFO - Started process (PID=552) to work on /opt/airflow/dags/gw2_dag.py
[2023-05-13T19:53:59.722+0000] {processor.py:743} INFO - Processing file /opt/airflow/dags/gw2_dag.py for tasks to queue
[2023-05-13T19:53:59.722+0000] {logging_mixin.py:137} INFO - [2023-05-13T19:53:59.722+0000] {dagbag.py:538} INFO - Filling up the DagBag from /opt/airflow/dags/gw2_dag.py
[2023-05-13T19:53:59.733+0000] {logging_mixin.py:137} INFO - [2023-05-13T19:53:59.732+0000] {dagbag.py:343} ERROR - Failed to import: /opt/airflow/dags/gw2_dag.py
Traceback (most recent call last):
  File "/home/airflow/.local/lib/python3.7/site-packages/airflow/models/dagbag.py", line 339, in parse
    loader.exec_module(new_module)
  File "<frozen importlib._bootstrap_external>", line 728, in exec_module
  File "<frozen importlib._bootstrap>", line 219, in _call_with_frames_removed
  File "/opt/airflow/dags/gw2_dag.py", line 16, in <module>
    from src.url_writer import url_writer_script
ModuleNotFoundError: No module named 'src'
[2023-05-13T19:53:59.733+0000] {processor.py:755} WARNING - No viable dags retrieved from /opt/airflow/dags/gw2_dag.py
[2023-05-13T19:53:59.751+0000] {processor.py:175} INFO - Processing /opt/airflow/dags/gw2_dag.py took 0.033 seconds
[2023-05-13T19:54:30.230+0000] {processor.py:153} INFO - Started process (PID=801) to work on /opt/airflow/dags/gw2_dag.py
[2023-05-13T19:54:30.230+0000] {processor.py:743} INFO - Processing file /opt/airflow/dags/gw2_dag.py for tasks to queue
[2023-05-13T19:54:30.231+0000] {logging_mixin.py:137} INFO - [2023-05-13T19:54:30.231+0000] {dagbag.py:538} INFO - Filling up the DagBag from /opt/airflow/dags/gw2_dag.py
[2023-05-13T19:54:30.243+0000] {logging_mixin.py:137} INFO - [2023-05-13T19:54:30.243+0000] {dagbag.py:343} ERROR - Failed to import: /opt/airflow/dags/gw2_dag.py
Traceback (most recent call last):
  File "/home/airflow/.local/lib/python3.7/site-packages/airflow/models/dagbag.py", line 339, in parse
    loader.exec_module(new_module)
  File "<frozen importlib._bootstrap_external>", line 728, in exec_module
  File "<frozen importlib._bootstrap>", line 219, in _call_with_frames_removed
  File "/opt/airflow/dags/gw2_dag.py", line 16, in <module>
    from src.url_writer import url_writer_script
ModuleNotFoundError: No module named 'src'
[2023-05-13T19:54:30.243+0000] {processor.py:755} WARNING - No viable dags retrieved from /opt/airflow/dags/gw2_dag.py
[2023-05-13T19:54:30.258+0000] {processor.py:175} INFO - Processing /opt/airflow/dags/gw2_dag.py took 0.031 seconds
[2023-05-13T19:55:37.470+0000] {processor.py:153} INFO - Started process (PID=181) to work on /opt/airflow/dags/gw2_dag.py
[2023-05-13T19:55:37.470+0000] {processor.py:743} INFO - Processing file /opt/airflow/dags/gw2_dag.py for tasks to queue
[2023-05-13T19:55:37.471+0000] {logging_mixin.py:137} INFO - [2023-05-13T19:55:37.471+0000] {dagbag.py:538} INFO - Filling up the DagBag from /opt/airflow/dags/gw2_dag.py
[2023-05-13T19:55:37.500+0000] {logging_mixin.py:137} INFO - [2023-05-13T19:55:37.499+0000] {dagbag.py:343} ERROR - Failed to import: /opt/airflow/dags/gw2_dag.py
Traceback (most recent call last):
  File "/home/airflow/.local/lib/python3.7/site-packages/airflow/models/dagbag.py", line 339, in parse
    loader.exec_module(new_module)
  File "<frozen importlib._bootstrap_external>", line 728, in exec_module
  File "<frozen importlib._bootstrap>", line 219, in _call_with_frames_removed
  File "/opt/airflow/dags/gw2_dag.py", line 16, in <module>
    from src.url_writer import url_writer_script
ModuleNotFoundError: No module named 'src'
[2023-05-13T19:55:37.501+0000] {processor.py:755} WARNING - No viable dags retrieved from /opt/airflow/dags/gw2_dag.py
[2023-05-13T19:55:37.707+0000] {processor.py:175} INFO - Processing /opt/airflow/dags/gw2_dag.py took 0.240 seconds
[2023-05-13T19:56:07.857+0000] {processor.py:153} INFO - Started process (PID=423) to work on /opt/airflow/dags/gw2_dag.py
[2023-05-13T19:56:07.858+0000] {processor.py:743} INFO - Processing file /opt/airflow/dags/gw2_dag.py for tasks to queue
[2023-05-13T19:56:07.858+0000] {logging_mixin.py:137} INFO - [2023-05-13T19:56:07.858+0000] {dagbag.py:538} INFO - Filling up the DagBag from /opt/airflow/dags/gw2_dag.py
[2023-05-13T19:56:07.872+0000] {logging_mixin.py:137} INFO - [2023-05-13T19:56:07.871+0000] {dagbag.py:343} ERROR - Failed to import: /opt/airflow/dags/gw2_dag.py
Traceback (most recent call last):
  File "/home/airflow/.local/lib/python3.7/site-packages/airflow/models/dagbag.py", line 339, in parse
    loader.exec_module(new_module)
  File "<frozen importlib._bootstrap_external>", line 728, in exec_module
  File "<frozen importlib._bootstrap>", line 219, in _call_with_frames_removed
  File "/opt/airflow/dags/gw2_dag.py", line 16, in <module>
    from src.url_writer import url_writer_script
ModuleNotFoundError: No module named 'src'
[2023-05-13T19:56:07.872+0000] {processor.py:755} WARNING - No viable dags retrieved from /opt/airflow/dags/gw2_dag.py
[2023-05-13T19:56:07.888+0000] {processor.py:175} INFO - Processing /opt/airflow/dags/gw2_dag.py took 0.033 seconds
[2023-05-13T19:56:38.684+0000] {processor.py:153} INFO - Started process (PID=671) to work on /opt/airflow/dags/gw2_dag.py
[2023-05-13T19:56:38.687+0000] {processor.py:743} INFO - Processing file /opt/airflow/dags/gw2_dag.py for tasks to queue
[2023-05-13T19:56:38.687+0000] {logging_mixin.py:137} INFO - [2023-05-13T19:56:38.687+0000] {dagbag.py:538} INFO - Filling up the DagBag from /opt/airflow/dags/gw2_dag.py
[2023-05-13T19:56:38.705+0000] {logging_mixin.py:137} INFO - [2023-05-13T19:56:38.704+0000] {dagbag.py:343} ERROR - Failed to import: /opt/airflow/dags/gw2_dag.py
Traceback (most recent call last):
  File "/home/airflow/.local/lib/python3.7/site-packages/airflow/models/dagbag.py", line 339, in parse
    loader.exec_module(new_module)
  File "<frozen importlib._bootstrap_external>", line 728, in exec_module
  File "<frozen importlib._bootstrap>", line 219, in _call_with_frames_removed
  File "/opt/airflow/dags/gw2_dag.py", line 16, in <module>
    from src.url_writer import url_writer_script
ModuleNotFoundError: No module named 'src'
[2023-05-13T19:56:38.705+0000] {processor.py:755} WARNING - No viable dags retrieved from /opt/airflow/dags/gw2_dag.py
[2023-05-13T19:56:38.725+0000] {processor.py:175} INFO - Processing /opt/airflow/dags/gw2_dag.py took 0.045 seconds
[2023-05-13T19:57:09.649+0000] {processor.py:153} INFO - Started process (PID=903) to work on /opt/airflow/dags/gw2_dag.py
[2023-05-13T19:57:09.650+0000] {processor.py:743} INFO - Processing file /opt/airflow/dags/gw2_dag.py for tasks to queue
[2023-05-13T19:57:09.650+0000] {logging_mixin.py:137} INFO - [2023-05-13T19:57:09.650+0000] {dagbag.py:538} INFO - Filling up the DagBag from /opt/airflow/dags/gw2_dag.py
[2023-05-13T19:57:09.665+0000] {logging_mixin.py:137} INFO - [2023-05-13T19:57:09.664+0000] {dagbag.py:343} ERROR - Failed to import: /opt/airflow/dags/gw2_dag.py
Traceback (most recent call last):
  File "/home/airflow/.local/lib/python3.7/site-packages/airflow/models/dagbag.py", line 339, in parse
    loader.exec_module(new_module)
  File "<frozen importlib._bootstrap_external>", line 728, in exec_module
  File "<frozen importlib._bootstrap>", line 219, in _call_with_frames_removed
  File "/opt/airflow/dags/gw2_dag.py", line 16, in <module>
    from src.url_writer import url_writer_script
ModuleNotFoundError: No module named 'src'
[2023-05-13T19:57:09.665+0000] {processor.py:755} WARNING - No viable dags retrieved from /opt/airflow/dags/gw2_dag.py
[2023-05-13T19:57:09.688+0000] {processor.py:175} INFO - Processing /opt/airflow/dags/gw2_dag.py took 0.041 seconds
[2023-05-13T19:57:40.035+0000] {processor.py:153} INFO - Started process (PID=1151) to work on /opt/airflow/dags/gw2_dag.py
[2023-05-13T19:57:40.036+0000] {processor.py:743} INFO - Processing file /opt/airflow/dags/gw2_dag.py for tasks to queue
[2023-05-13T19:57:40.036+0000] {logging_mixin.py:137} INFO - [2023-05-13T19:57:40.036+0000] {dagbag.py:538} INFO - Filling up the DagBag from /opt/airflow/dags/gw2_dag.py
[2023-05-13T19:57:40.054+0000] {logging_mixin.py:137} INFO - [2023-05-13T19:57:40.053+0000] {dagbag.py:343} ERROR - Failed to import: /opt/airflow/dags/gw2_dag.py
Traceback (most recent call last):
  File "/home/airflow/.local/lib/python3.7/site-packages/airflow/models/dagbag.py", line 339, in parse
    loader.exec_module(new_module)
  File "<frozen importlib._bootstrap_external>", line 728, in exec_module
  File "<frozen importlib._bootstrap>", line 219, in _call_with_frames_removed
  File "/opt/airflow/dags/gw2_dag.py", line 16, in <module>
    from src.url_writer import url_writer_script
ModuleNotFoundError: No module named 'src'
[2023-05-13T19:57:40.054+0000] {processor.py:755} WARNING - No viable dags retrieved from /opt/airflow/dags/gw2_dag.py
[2023-05-13T19:57:40.075+0000] {processor.py:175} INFO - Processing /opt/airflow/dags/gw2_dag.py took 0.043 seconds
[2023-05-13T19:58:10.574+0000] {processor.py:153} INFO - Started process (PID=1383) to work on /opt/airflow/dags/gw2_dag.py
[2023-05-13T19:58:10.577+0000] {processor.py:743} INFO - Processing file /opt/airflow/dags/gw2_dag.py for tasks to queue
[2023-05-13T19:58:10.577+0000] {logging_mixin.py:137} INFO - [2023-05-13T19:58:10.577+0000] {dagbag.py:538} INFO - Filling up the DagBag from /opt/airflow/dags/gw2_dag.py
[2023-05-13T19:58:10.586+0000] {logging_mixin.py:137} INFO - [2023-05-13T19:58:10.586+0000] {dagbag.py:343} ERROR - Failed to import: /opt/airflow/dags/gw2_dag.py
Traceback (most recent call last):
  File "/home/airflow/.local/lib/python3.7/site-packages/airflow/models/dagbag.py", line 339, in parse
    loader.exec_module(new_module)
  File "<frozen importlib._bootstrap_external>", line 728, in exec_module
  File "<frozen importlib._bootstrap>", line 219, in _call_with_frames_removed
  File "/opt/airflow/dags/gw2_dag.py", line 16, in <module>
    from src.url_writer import url_writer_script
ModuleNotFoundError: No module named 'src'
[2023-05-13T19:58:10.586+0000] {processor.py:755} WARNING - No viable dags retrieved from /opt/airflow/dags/gw2_dag.py
[2023-05-13T19:58:10.599+0000] {processor.py:175} INFO - Processing /opt/airflow/dags/gw2_dag.py took 0.027 seconds
[2023-05-13T19:58:40.671+0000] {processor.py:153} INFO - Started process (PID=1631) to work on /opt/airflow/dags/gw2_dag.py
[2023-05-13T19:58:40.672+0000] {processor.py:743} INFO - Processing file /opt/airflow/dags/gw2_dag.py for tasks to queue
[2023-05-13T19:58:40.672+0000] {logging_mixin.py:137} INFO - [2023-05-13T19:58:40.672+0000] {dagbag.py:538} INFO - Filling up the DagBag from /opt/airflow/dags/gw2_dag.py
[2023-05-13T19:58:40.687+0000] {logging_mixin.py:137} INFO - [2023-05-13T19:58:40.686+0000] {dagbag.py:343} ERROR - Failed to import: /opt/airflow/dags/gw2_dag.py
Traceback (most recent call last):
  File "/home/airflow/.local/lib/python3.7/site-packages/airflow/models/dagbag.py", line 339, in parse
    loader.exec_module(new_module)
  File "<frozen importlib._bootstrap_external>", line 728, in exec_module
  File "<frozen importlib._bootstrap>", line 219, in _call_with_frames_removed
  File "/opt/airflow/dags/gw2_dag.py", line 16, in <module>
    from src.url_writer import url_writer_script
ModuleNotFoundError: No module named 'src'
[2023-05-13T19:58:40.687+0000] {processor.py:755} WARNING - No viable dags retrieved from /opt/airflow/dags/gw2_dag.py
[2023-05-13T19:58:40.704+0000] {processor.py:175} INFO - Processing /opt/airflow/dags/gw2_dag.py took 0.035 seconds
[2023-05-13T19:59:10.956+0000] {processor.py:153} INFO - Started process (PID=1862) to work on /opt/airflow/dags/gw2_dag.py
[2023-05-13T19:59:10.958+0000] {processor.py:743} INFO - Processing file /opt/airflow/dags/gw2_dag.py for tasks to queue
[2023-05-13T19:59:10.959+0000] {logging_mixin.py:137} INFO - [2023-05-13T19:59:10.959+0000] {dagbag.py:538} INFO - Filling up the DagBag from /opt/airflow/dags/gw2_dag.py
[2023-05-13T19:59:10.969+0000] {logging_mixin.py:137} INFO - [2023-05-13T19:59:10.968+0000] {dagbag.py:343} ERROR - Failed to import: /opt/airflow/dags/gw2_dag.py
Traceback (most recent call last):
  File "/home/airflow/.local/lib/python3.7/site-packages/airflow/models/dagbag.py", line 339, in parse
    loader.exec_module(new_module)
  File "<frozen importlib._bootstrap_external>", line 728, in exec_module
  File "<frozen importlib._bootstrap>", line 219, in _call_with_frames_removed
  File "/opt/airflow/dags/gw2_dag.py", line 16, in <module>
    from src.url_writer import url_writer_script
ModuleNotFoundError: No module named 'src'
[2023-05-13T19:59:10.969+0000] {processor.py:755} WARNING - No viable dags retrieved from /opt/airflow/dags/gw2_dag.py
[2023-05-13T19:59:10.982+0000] {processor.py:175} INFO - Processing /opt/airflow/dags/gw2_dag.py took 0.028 seconds
[2023-05-13T19:59:41.058+0000] {processor.py:153} INFO - Started process (PID=2109) to work on /opt/airflow/dags/gw2_dag.py
[2023-05-13T19:59:41.059+0000] {processor.py:743} INFO - Processing file /opt/airflow/dags/gw2_dag.py for tasks to queue
[2023-05-13T19:59:41.059+0000] {logging_mixin.py:137} INFO - [2023-05-13T19:59:41.059+0000] {dagbag.py:538} INFO - Filling up the DagBag from /opt/airflow/dags/gw2_dag.py
[2023-05-13T19:59:41.073+0000] {logging_mixin.py:137} INFO - [2023-05-13T19:59:41.072+0000] {dagbag.py:343} ERROR - Failed to import: /opt/airflow/dags/gw2_dag.py
Traceback (most recent call last):
  File "/home/airflow/.local/lib/python3.7/site-packages/airflow/models/dagbag.py", line 339, in parse
    loader.exec_module(new_module)
  File "<frozen importlib._bootstrap_external>", line 728, in exec_module
  File "<frozen importlib._bootstrap>", line 219, in _call_with_frames_removed
  File "/opt/airflow/dags/gw2_dag.py", line 16, in <module>
    from src.url_writer import url_writer_script
ModuleNotFoundError: No module named 'src'
[2023-05-13T19:59:41.073+0000] {processor.py:755} WARNING - No viable dags retrieved from /opt/airflow/dags/gw2_dag.py
[2023-05-13T19:59:41.090+0000] {processor.py:175} INFO - Processing /opt/airflow/dags/gw2_dag.py took 0.034 seconds
[2023-05-13T20:00:11.958+0000] {processor.py:153} INFO - Started process (PID=2358) to work on /opt/airflow/dags/gw2_dag.py
[2023-05-13T20:00:11.959+0000] {processor.py:743} INFO - Processing file /opt/airflow/dags/gw2_dag.py for tasks to queue
[2023-05-13T20:00:11.960+0000] {logging_mixin.py:137} INFO - [2023-05-13T20:00:11.960+0000] {dagbag.py:538} INFO - Filling up the DagBag from /opt/airflow/dags/gw2_dag.py
[2023-05-13T20:00:11.973+0000] {logging_mixin.py:137} INFO - [2023-05-13T20:00:11.973+0000] {dagbag.py:343} ERROR - Failed to import: /opt/airflow/dags/gw2_dag.py
Traceback (most recent call last):
  File "/home/airflow/.local/lib/python3.7/site-packages/airflow/models/dagbag.py", line 339, in parse
    loader.exec_module(new_module)
  File "<frozen importlib._bootstrap_external>", line 728, in exec_module
  File "<frozen importlib._bootstrap>", line 219, in _call_with_frames_removed
  File "/opt/airflow/dags/gw2_dag.py", line 16, in <module>
    from src.url_writer import url_writer_script
ModuleNotFoundError: No module named 'src'
[2023-05-13T20:00:11.974+0000] {processor.py:755} WARNING - No viable dags retrieved from /opt/airflow/dags/gw2_dag.py
[2023-05-13T20:00:11.997+0000] {processor.py:175} INFO - Processing /opt/airflow/dags/gw2_dag.py took 0.042 seconds
[2023-05-13T20:00:42.895+0000] {processor.py:153} INFO - Started process (PID=2591) to work on /opt/airflow/dags/gw2_dag.py
[2023-05-13T20:00:42.896+0000] {processor.py:743} INFO - Processing file /opt/airflow/dags/gw2_dag.py for tasks to queue
[2023-05-13T20:00:42.897+0000] {logging_mixin.py:137} INFO - [2023-05-13T20:00:42.897+0000] {dagbag.py:538} INFO - Filling up the DagBag from /opt/airflow/dags/gw2_dag.py
[2023-05-13T20:00:42.910+0000] {logging_mixin.py:137} INFO - [2023-05-13T20:00:42.910+0000] {dagbag.py:343} ERROR - Failed to import: /opt/airflow/dags/gw2_dag.py
Traceback (most recent call last):
  File "/home/airflow/.local/lib/python3.7/site-packages/airflow/models/dagbag.py", line 339, in parse
    loader.exec_module(new_module)
  File "<frozen importlib._bootstrap_external>", line 728, in exec_module
  File "<frozen importlib._bootstrap>", line 219, in _call_with_frames_removed
  File "/opt/airflow/dags/gw2_dag.py", line 16, in <module>
    from src.url_writer import url_writer_script
ModuleNotFoundError: No module named 'src'
[2023-05-13T20:00:42.911+0000] {processor.py:755} WARNING - No viable dags retrieved from /opt/airflow/dags/gw2_dag.py
[2023-05-13T20:00:42.928+0000] {processor.py:175} INFO - Processing /opt/airflow/dags/gw2_dag.py took 0.036 seconds
[2023-05-13T20:01:13.057+0000] {processor.py:153} INFO - Started process (PID=2840) to work on /opt/airflow/dags/gw2_dag.py
[2023-05-13T20:01:13.059+0000] {processor.py:743} INFO - Processing file /opt/airflow/dags/gw2_dag.py for tasks to queue
[2023-05-13T20:01:13.060+0000] {logging_mixin.py:137} INFO - [2023-05-13T20:01:13.060+0000] {dagbag.py:538} INFO - Filling up the DagBag from /opt/airflow/dags/gw2_dag.py
[2023-05-13T20:01:13.076+0000] {logging_mixin.py:137} INFO - [2023-05-13T20:01:13.075+0000] {dagbag.py:343} ERROR - Failed to import: /opt/airflow/dags/gw2_dag.py
Traceback (most recent call last):
  File "/home/airflow/.local/lib/python3.7/site-packages/airflow/models/dagbag.py", line 339, in parse
    loader.exec_module(new_module)
  File "<frozen importlib._bootstrap_external>", line 728, in exec_module
  File "<frozen importlib._bootstrap>", line 219, in _call_with_frames_removed
  File "/opt/airflow/dags/gw2_dag.py", line 16, in <module>
    from src.url_writer import url_writer_script
ModuleNotFoundError: No module named 'src'
[2023-05-13T20:01:13.076+0000] {processor.py:755} WARNING - No viable dags retrieved from /opt/airflow/dags/gw2_dag.py
[2023-05-13T20:01:13.098+0000] {processor.py:175} INFO - Processing /opt/airflow/dags/gw2_dag.py took 0.045 seconds
[2023-05-13T20:01:29.092+0000] {processor.py:153} INFO - Started process (PID=3056) to work on /opt/airflow/dags/gw2_dag.py
[2023-05-13T20:01:29.095+0000] {processor.py:743} INFO - Processing file /opt/airflow/dags/gw2_dag.py for tasks to queue
[2023-05-13T20:01:29.096+0000] {logging_mixin.py:137} INFO - [2023-05-13T20:01:29.096+0000] {dagbag.py:538} INFO - Filling up the DagBag from /opt/airflow/dags/gw2_dag.py
[2023-05-13T20:01:29.110+0000] {logging_mixin.py:137} INFO - [2023-05-13T20:01:29.109+0000] {dagbag.py:343} ERROR - Failed to import: /opt/airflow/dags/gw2_dag.py
Traceback (most recent call last):
  File "/home/airflow/.local/lib/python3.7/site-packages/airflow/models/dagbag.py", line 339, in parse
    loader.exec_module(new_module)
  File "<frozen importlib._bootstrap_external>", line 728, in exec_module
  File "<frozen importlib._bootstrap>", line 219, in _call_with_frames_removed
  File "/opt/airflow/dags/gw2_dag.py", line 17, in <module>
    from src.url_writer import url_writer_script
ModuleNotFoundError: No module named 'src'
[2023-05-13T20:01:29.110+0000] {processor.py:755} WARNING - No viable dags retrieved from /opt/airflow/dags/gw2_dag.py
[2023-05-13T20:01:29.126+0000] {processor.py:175} INFO - Processing /opt/airflow/dags/gw2_dag.py took 0.037 seconds
[2023-05-13T20:01:59.202+0000] {processor.py:153} INFO - Started process (PID=3297) to work on /opt/airflow/dags/gw2_dag.py
[2023-05-13T20:01:59.205+0000] {processor.py:743} INFO - Processing file /opt/airflow/dags/gw2_dag.py for tasks to queue
[2023-05-13T20:01:59.206+0000] {logging_mixin.py:137} INFO - [2023-05-13T20:01:59.206+0000] {dagbag.py:538} INFO - Filling up the DagBag from /opt/airflow/dags/gw2_dag.py
[2023-05-13T20:01:59.221+0000] {logging_mixin.py:137} INFO - [2023-05-13T20:01:59.221+0000] {dagbag.py:343} ERROR - Failed to import: /opt/airflow/dags/gw2_dag.py
Traceback (most recent call last):
  File "/home/airflow/.local/lib/python3.7/site-packages/airflow/models/dagbag.py", line 339, in parse
    loader.exec_module(new_module)
  File "<frozen importlib._bootstrap_external>", line 728, in exec_module
  File "<frozen importlib._bootstrap>", line 219, in _call_with_frames_removed
  File "/opt/airflow/dags/gw2_dag.py", line 17, in <module>
    from src.url_writer import url_writer_script
ModuleNotFoundError: No module named 'src'
[2023-05-13T20:01:59.222+0000] {processor.py:755} WARNING - No viable dags retrieved from /opt/airflow/dags/gw2_dag.py
[2023-05-13T20:01:59.239+0000] {processor.py:175} INFO - Processing /opt/airflow/dags/gw2_dag.py took 0.040 seconds
[2023-05-13T20:02:29.498+0000] {processor.py:153} INFO - Started process (PID=3536) to work on /opt/airflow/dags/gw2_dag.py
[2023-05-13T20:02:29.500+0000] {processor.py:743} INFO - Processing file /opt/airflow/dags/gw2_dag.py for tasks to queue
[2023-05-13T20:02:29.501+0000] {logging_mixin.py:137} INFO - [2023-05-13T20:02:29.501+0000] {dagbag.py:538} INFO - Filling up the DagBag from /opt/airflow/dags/gw2_dag.py
[2023-05-13T20:02:29.510+0000] {logging_mixin.py:137} INFO - [2023-05-13T20:02:29.510+0000] {dagbag.py:343} ERROR - Failed to import: /opt/airflow/dags/gw2_dag.py
Traceback (most recent call last):
  File "/home/airflow/.local/lib/python3.7/site-packages/airflow/models/dagbag.py", line 339, in parse
    loader.exec_module(new_module)
  File "<frozen importlib._bootstrap_external>", line 728, in exec_module
  File "<frozen importlib._bootstrap>", line 219, in _call_with_frames_removed
  File "/opt/airflow/dags/gw2_dag.py", line 17, in <module>
    from src.url_writer import url_writer_script
ModuleNotFoundError: No module named 'src'
[2023-05-13T20:02:29.510+0000] {processor.py:755} WARNING - No viable dags retrieved from /opt/airflow/dags/gw2_dag.py
[2023-05-13T20:02:29.523+0000] {processor.py:175} INFO - Processing /opt/airflow/dags/gw2_dag.py took 0.027 seconds
[2023-05-13T20:02:59.794+0000] {processor.py:153} INFO - Started process (PID=3776) to work on /opt/airflow/dags/gw2_dag.py
[2023-05-13T20:02:59.794+0000] {processor.py:743} INFO - Processing file /opt/airflow/dags/gw2_dag.py for tasks to queue
[2023-05-13T20:02:59.795+0000] {logging_mixin.py:137} INFO - [2023-05-13T20:02:59.795+0000] {dagbag.py:538} INFO - Filling up the DagBag from /opt/airflow/dags/gw2_dag.py
[2023-05-13T20:02:59.807+0000] {logging_mixin.py:137} INFO - [2023-05-13T20:02:59.807+0000] {dagbag.py:343} ERROR - Failed to import: /opt/airflow/dags/gw2_dag.py
Traceback (most recent call last):
  File "/home/airflow/.local/lib/python3.7/site-packages/airflow/models/dagbag.py", line 339, in parse
    loader.exec_module(new_module)
  File "<frozen importlib._bootstrap_external>", line 728, in exec_module
  File "<frozen importlib._bootstrap>", line 219, in _call_with_frames_removed
  File "/opt/airflow/dags/gw2_dag.py", line 17, in <module>
    from src.url_writer import url_writer_script
ModuleNotFoundError: No module named 'src'
[2023-05-13T20:02:59.808+0000] {processor.py:755} WARNING - No viable dags retrieved from /opt/airflow/dags/gw2_dag.py
[2023-05-13T20:02:59.824+0000] {processor.py:175} INFO - Processing /opt/airflow/dags/gw2_dag.py took 0.033 seconds
[2023-05-13T20:03:29.967+0000] {processor.py:153} INFO - Started process (PID=4014) to work on /opt/airflow/dags/gw2_dag.py
[2023-05-13T20:03:29.969+0000] {processor.py:743} INFO - Processing file /opt/airflow/dags/gw2_dag.py for tasks to queue
[2023-05-13T20:03:29.970+0000] {logging_mixin.py:137} INFO - [2023-05-13T20:03:29.970+0000] {dagbag.py:538} INFO - Filling up the DagBag from /opt/airflow/dags/gw2_dag.py
[2023-05-13T20:03:29.983+0000] {logging_mixin.py:137} INFO - [2023-05-13T20:03:29.982+0000] {dagbag.py:343} ERROR - Failed to import: /opt/airflow/dags/gw2_dag.py
Traceback (most recent call last):
  File "/home/airflow/.local/lib/python3.7/site-packages/airflow/models/dagbag.py", line 339, in parse
    loader.exec_module(new_module)
  File "<frozen importlib._bootstrap_external>", line 728, in exec_module
  File "<frozen importlib._bootstrap>", line 219, in _call_with_frames_removed
  File "/opt/airflow/dags/gw2_dag.py", line 17, in <module>
    from src.url_writer import url_writer_script
ModuleNotFoundError: No module named 'src'
[2023-05-13T20:03:29.983+0000] {processor.py:755} WARNING - No viable dags retrieved from /opt/airflow/dags/gw2_dag.py
[2023-05-13T20:03:29.999+0000] {processor.py:175} INFO - Processing /opt/airflow/dags/gw2_dag.py took 0.035 seconds
[2023-05-13T20:04:00.507+0000] {processor.py:153} INFO - Started process (PID=4262) to work on /opt/airflow/dags/gw2_dag.py
[2023-05-13T20:04:00.508+0000] {processor.py:743} INFO - Processing file /opt/airflow/dags/gw2_dag.py for tasks to queue
[2023-05-13T20:04:00.508+0000] {logging_mixin.py:137} INFO - [2023-05-13T20:04:00.508+0000] {dagbag.py:538} INFO - Filling up the DagBag from /opt/airflow/dags/gw2_dag.py
[2023-05-13T20:04:00.521+0000] {logging_mixin.py:137} INFO - [2023-05-13T20:04:00.520+0000] {dagbag.py:343} ERROR - Failed to import: /opt/airflow/dags/gw2_dag.py
Traceback (most recent call last):
  File "/home/airflow/.local/lib/python3.7/site-packages/airflow/models/dagbag.py", line 339, in parse
    loader.exec_module(new_module)
  File "<frozen importlib._bootstrap_external>", line 728, in exec_module
  File "<frozen importlib._bootstrap>", line 219, in _call_with_frames_removed
  File "/opt/airflow/dags/gw2_dag.py", line 17, in <module>
    from src.url_writer import url_writer_script
ModuleNotFoundError: No module named 'src'
[2023-05-13T20:04:00.521+0000] {processor.py:755} WARNING - No viable dags retrieved from /opt/airflow/dags/gw2_dag.py
[2023-05-13T20:04:00.538+0000] {processor.py:175} INFO - Processing /opt/airflow/dags/gw2_dag.py took 0.033 seconds
[2023-05-13T20:04:30.793+0000] {processor.py:153} INFO - Started process (PID=4494) to work on /opt/airflow/dags/gw2_dag.py
[2023-05-13T20:04:30.794+0000] {processor.py:743} INFO - Processing file /opt/airflow/dags/gw2_dag.py for tasks to queue
[2023-05-13T20:04:30.794+0000] {logging_mixin.py:137} INFO - [2023-05-13T20:04:30.794+0000] {dagbag.py:538} INFO - Filling up the DagBag from /opt/airflow/dags/gw2_dag.py
[2023-05-13T20:04:30.806+0000] {logging_mixin.py:137} INFO - [2023-05-13T20:04:30.806+0000] {dagbag.py:343} ERROR - Failed to import: /opt/airflow/dags/gw2_dag.py
Traceback (most recent call last):
  File "/home/airflow/.local/lib/python3.7/site-packages/airflow/models/dagbag.py", line 339, in parse
    loader.exec_module(new_module)
  File "<frozen importlib._bootstrap_external>", line 728, in exec_module
  File "<frozen importlib._bootstrap>", line 219, in _call_with_frames_removed
  File "/opt/airflow/dags/gw2_dag.py", line 17, in <module>
    from src.url_writer import url_writer_script
ModuleNotFoundError: No module named 'src'
[2023-05-13T20:04:30.807+0000] {processor.py:755} WARNING - No viable dags retrieved from /opt/airflow/dags/gw2_dag.py
[2023-05-13T20:04:30.823+0000] {processor.py:175} INFO - Processing /opt/airflow/dags/gw2_dag.py took 0.032 seconds
[2023-05-13T20:05:01.199+0000] {processor.py:153} INFO - Started process (PID=4742) to work on /opt/airflow/dags/gw2_dag.py
[2023-05-13T20:05:01.201+0000] {processor.py:743} INFO - Processing file /opt/airflow/dags/gw2_dag.py for tasks to queue
[2023-05-13T20:05:01.201+0000] {logging_mixin.py:137} INFO - [2023-05-13T20:05:01.201+0000] {dagbag.py:538} INFO - Filling up the DagBag from /opt/airflow/dags/gw2_dag.py
[2023-05-13T20:05:01.221+0000] {logging_mixin.py:137} INFO - [2023-05-13T20:05:01.220+0000] {dagbag.py:343} ERROR - Failed to import: /opt/airflow/dags/gw2_dag.py
Traceback (most recent call last):
  File "/home/airflow/.local/lib/python3.7/site-packages/airflow/models/dagbag.py", line 339, in parse
    loader.exec_module(new_module)
  File "<frozen importlib._bootstrap_external>", line 728, in exec_module
  File "<frozen importlib._bootstrap>", line 219, in _call_with_frames_removed
  File "/opt/airflow/dags/gw2_dag.py", line 17, in <module>
    from src.url_writer import url_writer_script
ModuleNotFoundError: No module named 'src'
[2023-05-13T20:05:01.221+0000] {processor.py:755} WARNING - No viable dags retrieved from /opt/airflow/dags/gw2_dag.py
[2023-05-13T20:05:01.251+0000] {processor.py:175} INFO - Processing /opt/airflow/dags/gw2_dag.py took 0.055 seconds
[2023-05-13T20:05:50.824+0000] {processor.py:153} INFO - Started process (PID=174) to work on /opt/airflow/dags/gw2_dag.py
[2023-05-13T20:05:50.825+0000] {processor.py:743} INFO - Processing file /opt/airflow/dags/gw2_dag.py for tasks to queue
[2023-05-13T20:05:50.826+0000] {logging_mixin.py:137} INFO - [2023-05-13T20:05:50.825+0000] {dagbag.py:538} INFO - Filling up the DagBag from /opt/airflow/dags/gw2_dag.py
[2023-05-13T20:05:50.846+0000] {logging_mixin.py:137} INFO - [2023-05-13T20:05:50.845+0000] {dagbag.py:343} ERROR - Failed to import: /opt/airflow/dags/gw2_dag.py
Traceback (most recent call last):
  File "/home/airflow/.local/lib/python3.7/site-packages/airflow/models/dagbag.py", line 339, in parse
    loader.exec_module(new_module)
  File "<frozen importlib._bootstrap_external>", line 728, in exec_module
  File "<frozen importlib._bootstrap>", line 219, in _call_with_frames_removed
  File "/opt/airflow/dags/gw2_dag.py", line 17, in <module>
    from src.url_writer import url_writer_script
ModuleNotFoundError: No module named 'src'
[2023-05-13T20:05:50.846+0000] {processor.py:755} WARNING - No viable dags retrieved from /opt/airflow/dags/gw2_dag.py
[2023-05-13T20:05:50.992+0000] {processor.py:175} INFO - Processing /opt/airflow/dags/gw2_dag.py took 0.170 seconds
[2023-05-13T20:06:21.791+0000] {processor.py:153} INFO - Started process (PID=423) to work on /opt/airflow/dags/gw2_dag.py
[2023-05-13T20:06:21.794+0000] {processor.py:743} INFO - Processing file /opt/airflow/dags/gw2_dag.py for tasks to queue
[2023-05-13T20:06:21.794+0000] {logging_mixin.py:137} INFO - [2023-05-13T20:06:21.794+0000] {dagbag.py:538} INFO - Filling up the DagBag from /opt/airflow/dags/gw2_dag.py
[2023-05-13T20:06:21.807+0000] {logging_mixin.py:137} INFO - [2023-05-13T20:06:21.806+0000] {dagbag.py:343} ERROR - Failed to import: /opt/airflow/dags/gw2_dag.py
Traceback (most recent call last):
  File "/home/airflow/.local/lib/python3.7/site-packages/airflow/models/dagbag.py", line 339, in parse
    loader.exec_module(new_module)
  File "<frozen importlib._bootstrap_external>", line 728, in exec_module
  File "<frozen importlib._bootstrap>", line 219, in _call_with_frames_removed
  File "/opt/airflow/dags/gw2_dag.py", line 17, in <module>
    from src.url_writer import url_writer_script
ModuleNotFoundError: No module named 'src'
[2023-05-13T20:06:21.807+0000] {processor.py:755} WARNING - No viable dags retrieved from /opt/airflow/dags/gw2_dag.py
[2023-05-13T20:06:21.824+0000] {processor.py:175} INFO - Processing /opt/airflow/dags/gw2_dag.py took 0.035 seconds
[2023-05-13T20:06:52.033+0000] {processor.py:153} INFO - Started process (PID=662) to work on /opt/airflow/dags/gw2_dag.py
[2023-05-13T20:06:52.034+0000] {processor.py:743} INFO - Processing file /opt/airflow/dags/gw2_dag.py for tasks to queue
[2023-05-13T20:06:52.034+0000] {logging_mixin.py:137} INFO - [2023-05-13T20:06:52.034+0000] {dagbag.py:538} INFO - Filling up the DagBag from /opt/airflow/dags/gw2_dag.py
[2023-05-13T20:06:52.054+0000] {logging_mixin.py:137} INFO - [2023-05-13T20:06:52.053+0000] {dagbag.py:343} ERROR - Failed to import: /opt/airflow/dags/gw2_dag.py
Traceback (most recent call last):
  File "/home/airflow/.local/lib/python3.7/site-packages/airflow/models/dagbag.py", line 339, in parse
    loader.exec_module(new_module)
  File "<frozen importlib._bootstrap_external>", line 728, in exec_module
  File "<frozen importlib._bootstrap>", line 219, in _call_with_frames_removed
  File "/opt/airflow/dags/gw2_dag.py", line 17, in <module>
    from src.url_writer import url_writer_script
ModuleNotFoundError: No module named 'src'
[2023-05-13T20:06:52.055+0000] {processor.py:755} WARNING - No viable dags retrieved from /opt/airflow/dags/gw2_dag.py
[2023-05-13T20:06:52.077+0000] {processor.py:175} INFO - Processing /opt/airflow/dags/gw2_dag.py took 0.047 seconds
[2023-05-13T20:07:22.858+0000] {processor.py:153} INFO - Started process (PID=903) to work on /opt/airflow/dags/gw2_dag.py
[2023-05-13T20:07:22.859+0000] {processor.py:743} INFO - Processing file /opt/airflow/dags/gw2_dag.py for tasks to queue
[2023-05-13T20:07:22.859+0000] {logging_mixin.py:137} INFO - [2023-05-13T20:07:22.859+0000] {dagbag.py:538} INFO - Filling up the DagBag from /opt/airflow/dags/gw2_dag.py
[2023-05-13T20:07:22.872+0000] {logging_mixin.py:137} INFO - [2023-05-13T20:07:22.872+0000] {dagbag.py:343} ERROR - Failed to import: /opt/airflow/dags/gw2_dag.py
Traceback (most recent call last):
  File "/home/airflow/.local/lib/python3.7/site-packages/airflow/models/dagbag.py", line 339, in parse
    loader.exec_module(new_module)
  File "<frozen importlib._bootstrap_external>", line 728, in exec_module
  File "<frozen importlib._bootstrap>", line 219, in _call_with_frames_removed
  File "/opt/airflow/dags/gw2_dag.py", line 17, in <module>
    from src.url_writer import url_writer_script
ModuleNotFoundError: No module named 'src'
[2023-05-13T20:07:22.873+0000] {processor.py:755} WARNING - No viable dags retrieved from /opt/airflow/dags/gw2_dag.py
[2023-05-13T20:07:22.890+0000] {processor.py:175} INFO - Processing /opt/airflow/dags/gw2_dag.py took 0.034 seconds
[2023-05-13T20:08:45.761+0000] {processor.py:153} INFO - Started process (PID=192) to work on /opt/airflow/dags/gw2_dag.py
[2023-05-13T20:08:45.762+0000] {processor.py:743} INFO - Processing file /opt/airflow/dags/gw2_dag.py for tasks to queue
[2023-05-13T20:08:45.763+0000] {logging_mixin.py:137} INFO - [2023-05-13T20:08:45.762+0000] {dagbag.py:538} INFO - Filling up the DagBag from /opt/airflow/dags/gw2_dag.py
[2023-05-13T20:08:45.793+0000] {logging_mixin.py:137} INFO - [2023-05-13T20:08:45.792+0000] {dagbag.py:343} ERROR - Failed to import: /opt/airflow/dags/gw2_dag.py
Traceback (most recent call last):
  File "/home/airflow/.local/lib/python3.7/site-packages/airflow/models/dagbag.py", line 339, in parse
    loader.exec_module(new_module)
  File "<frozen importlib._bootstrap_external>", line 728, in exec_module
  File "<frozen importlib._bootstrap>", line 219, in _call_with_frames_removed
  File "/opt/airflow/dags/gw2_dag.py", line 20, in <module>
    from src.main_etl import gw2_etl
  File "/opt/airflow/plugins/src/main_etl.py", line 17, in <module>
    import pymongo
ModuleNotFoundError: No module named 'pymongo'
[2023-05-13T20:08:45.793+0000] {processor.py:755} WARNING - No viable dags retrieved from /opt/airflow/dags/gw2_dag.py
[2023-05-13T20:08:45.806+0000] {processor.py:175} INFO - Processing /opt/airflow/dags/gw2_dag.py took 0.048 seconds
[2023-05-13T20:09:16.562+0000] {processor.py:153} INFO - Started process (PID=424) to work on /opt/airflow/dags/gw2_dag.py
[2023-05-13T20:09:16.565+0000] {processor.py:743} INFO - Processing file /opt/airflow/dags/gw2_dag.py for tasks to queue
[2023-05-13T20:09:16.566+0000] {logging_mixin.py:137} INFO - [2023-05-13T20:09:16.566+0000] {dagbag.py:538} INFO - Filling up the DagBag from /opt/airflow/dags/gw2_dag.py
[2023-05-13T20:09:16.586+0000] {logging_mixin.py:137} INFO - [2023-05-13T20:09:16.585+0000] {dagbag.py:343} ERROR - Failed to import: /opt/airflow/dags/gw2_dag.py
Traceback (most recent call last):
  File "/home/airflow/.local/lib/python3.7/site-packages/airflow/models/dagbag.py", line 339, in parse
    loader.exec_module(new_module)
  File "<frozen importlib._bootstrap_external>", line 728, in exec_module
  File "<frozen importlib._bootstrap>", line 219, in _call_with_frames_removed
  File "/opt/airflow/dags/gw2_dag.py", line 20, in <module>
    from src.main_etl import gw2_etl
  File "/opt/airflow/plugins/src/main_etl.py", line 17, in <module>
    import pymongo
ModuleNotFoundError: No module named 'pymongo'
[2023-05-13T20:09:16.587+0000] {processor.py:755} WARNING - No viable dags retrieved from /opt/airflow/dags/gw2_dag.py
[2023-05-13T20:09:16.608+0000] {processor.py:175} INFO - Processing /opt/airflow/dags/gw2_dag.py took 0.048 seconds
[2023-05-13T20:09:47.303+0000] {processor.py:153} INFO - Started process (PID=678) to work on /opt/airflow/dags/gw2_dag.py
[2023-05-13T20:09:47.306+0000] {processor.py:743} INFO - Processing file /opt/airflow/dags/gw2_dag.py for tasks to queue
[2023-05-13T20:09:47.307+0000] {logging_mixin.py:137} INFO - [2023-05-13T20:09:47.307+0000] {dagbag.py:538} INFO - Filling up the DagBag from /opt/airflow/dags/gw2_dag.py
[2023-05-13T20:09:47.326+0000] {logging_mixin.py:137} INFO - [2023-05-13T20:09:47.325+0000] {dagbag.py:343} ERROR - Failed to import: /opt/airflow/dags/gw2_dag.py
Traceback (most recent call last):
  File "/home/airflow/.local/lib/python3.7/site-packages/airflow/models/dagbag.py", line 339, in parse
    loader.exec_module(new_module)
  File "<frozen importlib._bootstrap_external>", line 728, in exec_module
  File "<frozen importlib._bootstrap>", line 219, in _call_with_frames_removed
  File "/opt/airflow/dags/gw2_dag.py", line 20, in <module>
    from src.main_etl import gw2_etl
  File "/opt/airflow/plugins/src/main_etl.py", line 17, in <module>
    import pymongo
ModuleNotFoundError: No module named 'pymongo'
[2023-05-13T20:09:47.327+0000] {processor.py:755} WARNING - No viable dags retrieved from /opt/airflow/dags/gw2_dag.py
[2023-05-13T20:09:47.344+0000] {processor.py:175} INFO - Processing /opt/airflow/dags/gw2_dag.py took 0.044 seconds
[2023-05-13T20:10:17.579+0000] {processor.py:153} INFO - Started process (PID=913) to work on /opt/airflow/dags/gw2_dag.py
[2023-05-13T20:10:17.581+0000] {processor.py:743} INFO - Processing file /opt/airflow/dags/gw2_dag.py for tasks to queue
[2023-05-13T20:10:17.582+0000] {logging_mixin.py:137} INFO - [2023-05-13T20:10:17.582+0000] {dagbag.py:538} INFO - Filling up the DagBag from /opt/airflow/dags/gw2_dag.py
[2023-05-13T20:10:17.596+0000] {logging_mixin.py:137} INFO - [2023-05-13T20:10:17.595+0000] {dagbag.py:343} ERROR - Failed to import: /opt/airflow/dags/gw2_dag.py
Traceback (most recent call last):
  File "/home/airflow/.local/lib/python3.7/site-packages/airflow/models/dagbag.py", line 339, in parse
    loader.exec_module(new_module)
  File "<frozen importlib._bootstrap_external>", line 728, in exec_module
  File "<frozen importlib._bootstrap>", line 219, in _call_with_frames_removed
  File "/opt/airflow/dags/gw2_dag.py", line 20, in <module>
    from src.main_etl import gw2_etl
  File "/opt/airflow/plugins/src/main_etl.py", line 17, in <module>
    import pymongo
ModuleNotFoundError: No module named 'pymongo'
[2023-05-13T20:10:17.596+0000] {processor.py:755} WARNING - No viable dags retrieved from /opt/airflow/dags/gw2_dag.py
[2023-05-13T20:10:17.611+0000] {processor.py:175} INFO - Processing /opt/airflow/dags/gw2_dag.py took 0.034 seconds
[2023-05-13T20:10:47.777+0000] {processor.py:153} INFO - Started process (PID=1161) to work on /opt/airflow/dags/gw2_dag.py
[2023-05-13T20:10:47.778+0000] {processor.py:743} INFO - Processing file /opt/airflow/dags/gw2_dag.py for tasks to queue
[2023-05-13T20:10:47.778+0000] {logging_mixin.py:137} INFO - [2023-05-13T20:10:47.778+0000] {dagbag.py:538} INFO - Filling up the DagBag from /opt/airflow/dags/gw2_dag.py
[2023-05-13T20:10:47.792+0000] {logging_mixin.py:137} INFO - [2023-05-13T20:10:47.792+0000] {dagbag.py:343} ERROR - Failed to import: /opt/airflow/dags/gw2_dag.py
Traceback (most recent call last):
  File "/home/airflow/.local/lib/python3.7/site-packages/airflow/models/dagbag.py", line 339, in parse
    loader.exec_module(new_module)
  File "<frozen importlib._bootstrap_external>", line 728, in exec_module
  File "<frozen importlib._bootstrap>", line 219, in _call_with_frames_removed
  File "/opt/airflow/dags/gw2_dag.py", line 20, in <module>
    from src.main_etl import gw2_etl
  File "/opt/airflow/plugins/src/main_etl.py", line 17, in <module>
    import pymongo
ModuleNotFoundError: No module named 'pymongo'
[2023-05-13T20:10:47.793+0000] {processor.py:755} WARNING - No viable dags retrieved from /opt/airflow/dags/gw2_dag.py
[2023-05-13T20:10:47.810+0000] {processor.py:175} INFO - Processing /opt/airflow/dags/gw2_dag.py took 0.035 seconds
[2023-05-13T20:11:18.017+0000] {processor.py:153} INFO - Started process (PID=1392) to work on /opt/airflow/dags/gw2_dag.py
[2023-05-13T20:11:18.019+0000] {processor.py:743} INFO - Processing file /opt/airflow/dags/gw2_dag.py for tasks to queue
[2023-05-13T20:11:18.020+0000] {logging_mixin.py:137} INFO - [2023-05-13T20:11:18.020+0000] {dagbag.py:538} INFO - Filling up the DagBag from /opt/airflow/dags/gw2_dag.py
[2023-05-13T20:11:18.034+0000] {logging_mixin.py:137} INFO - [2023-05-13T20:11:18.033+0000] {dagbag.py:343} ERROR - Failed to import: /opt/airflow/dags/gw2_dag.py
Traceback (most recent call last):
  File "/home/airflow/.local/lib/python3.7/site-packages/airflow/models/dagbag.py", line 339, in parse
    loader.exec_module(new_module)
  File "<frozen importlib._bootstrap_external>", line 728, in exec_module
  File "<frozen importlib._bootstrap>", line 219, in _call_with_frames_removed
  File "/opt/airflow/dags/gw2_dag.py", line 20, in <module>
    from src.main_etl import gw2_etl
  File "/opt/airflow/plugins/src/main_etl.py", line 17, in <module>
    import pymongo
ModuleNotFoundError: No module named 'pymongo'
[2023-05-13T20:11:18.034+0000] {processor.py:755} WARNING - No viable dags retrieved from /opt/airflow/dags/gw2_dag.py
[2023-05-13T20:11:18.051+0000] {processor.py:175} INFO - Processing /opt/airflow/dags/gw2_dag.py took 0.036 seconds
[2023-05-13T20:11:48.962+0000] {processor.py:153} INFO - Started process (PID=1641) to work on /opt/airflow/dags/gw2_dag.py
[2023-05-13T20:11:48.965+0000] {processor.py:743} INFO - Processing file /opt/airflow/dags/gw2_dag.py for tasks to queue
[2023-05-13T20:11:48.965+0000] {logging_mixin.py:137} INFO - [2023-05-13T20:11:48.965+0000] {dagbag.py:538} INFO - Filling up the DagBag from /opt/airflow/dags/gw2_dag.py
[2023-05-13T20:11:48.982+0000] {logging_mixin.py:137} INFO - [2023-05-13T20:11:48.981+0000] {dagbag.py:343} ERROR - Failed to import: /opt/airflow/dags/gw2_dag.py
Traceback (most recent call last):
  File "/home/airflow/.local/lib/python3.7/site-packages/airflow/models/dagbag.py", line 339, in parse
    loader.exec_module(new_module)
  File "<frozen importlib._bootstrap_external>", line 728, in exec_module
  File "<frozen importlib._bootstrap>", line 219, in _call_with_frames_removed
  File "/opt/airflow/dags/gw2_dag.py", line 20, in <module>
    from src.main_etl import gw2_etl
  File "/opt/airflow/plugins/src/main_etl.py", line 17, in <module>
    import pymongo
ModuleNotFoundError: No module named 'pymongo'
[2023-05-13T20:11:48.982+0000] {processor.py:755} WARNING - No viable dags retrieved from /opt/airflow/dags/gw2_dag.py
[2023-05-13T20:11:49.000+0000] {processor.py:175} INFO - Processing /opt/airflow/dags/gw2_dag.py took 0.040 seconds
[2023-05-13T20:12:19.164+0000] {processor.py:153} INFO - Started process (PID=1882) to work on /opt/airflow/dags/gw2_dag.py
[2023-05-13T20:12:19.165+0000] {processor.py:743} INFO - Processing file /opt/airflow/dags/gw2_dag.py for tasks to queue
[2023-05-13T20:12:19.165+0000] {logging_mixin.py:137} INFO - [2023-05-13T20:12:19.165+0000] {dagbag.py:538} INFO - Filling up the DagBag from /opt/airflow/dags/gw2_dag.py
[2023-05-13T20:12:19.180+0000] {logging_mixin.py:137} INFO - [2023-05-13T20:12:19.179+0000] {dagbag.py:343} ERROR - Failed to import: /opt/airflow/dags/gw2_dag.py
Traceback (most recent call last):
  File "/home/airflow/.local/lib/python3.7/site-packages/airflow/models/dagbag.py", line 339, in parse
    loader.exec_module(new_module)
  File "<frozen importlib._bootstrap_external>", line 728, in exec_module
  File "<frozen importlib._bootstrap>", line 219, in _call_with_frames_removed
  File "/opt/airflow/dags/gw2_dag.py", line 20, in <module>
    from src.main_etl import gw2_etl
  File "/opt/airflow/plugins/src/main_etl.py", line 17, in <module>
    import pymongo
ModuleNotFoundError: No module named 'pymongo'
[2023-05-13T20:12:19.181+0000] {processor.py:755} WARNING - No viable dags retrieved from /opt/airflow/dags/gw2_dag.py
[2023-05-13T20:12:19.202+0000] {processor.py:175} INFO - Processing /opt/airflow/dags/gw2_dag.py took 0.040 seconds
[2023-05-13T20:12:49.944+0000] {processor.py:153} INFO - Started process (PID=2121) to work on /opt/airflow/dags/gw2_dag.py
[2023-05-13T20:12:49.947+0000] {processor.py:743} INFO - Processing file /opt/airflow/dags/gw2_dag.py for tasks to queue
[2023-05-13T20:12:49.948+0000] {logging_mixin.py:137} INFO - [2023-05-13T20:12:49.948+0000] {dagbag.py:538} INFO - Filling up the DagBag from /opt/airflow/dags/gw2_dag.py
[2023-05-13T20:12:49.958+0000] {logging_mixin.py:137} INFO - [2023-05-13T20:12:49.957+0000] {dagbag.py:343} ERROR - Failed to import: /opt/airflow/dags/gw2_dag.py
Traceback (most recent call last):
  File "/home/airflow/.local/lib/python3.7/site-packages/airflow/models/dagbag.py", line 339, in parse
    loader.exec_module(new_module)
  File "<frozen importlib._bootstrap_external>", line 728, in exec_module
  File "<frozen importlib._bootstrap>", line 219, in _call_with_frames_removed
  File "/opt/airflow/dags/gw2_dag.py", line 20, in <module>
    from src.main_etl import gw2_etl
  File "/opt/airflow/plugins/src/main_etl.py", line 17, in <module>
    import pymongo
ModuleNotFoundError: No module named 'pymongo'
[2023-05-13T20:12:49.958+0000] {processor.py:755} WARNING - No viable dags retrieved from /opt/airflow/dags/gw2_dag.py
[2023-05-13T20:12:49.971+0000] {processor.py:175} INFO - Processing /opt/airflow/dags/gw2_dag.py took 0.029 seconds
[2023-05-13T20:13:20.685+0000] {processor.py:153} INFO - Started process (PID=2369) to work on /opt/airflow/dags/gw2_dag.py
[2023-05-13T20:13:20.685+0000] {processor.py:743} INFO - Processing file /opt/airflow/dags/gw2_dag.py for tasks to queue
[2023-05-13T20:13:20.686+0000] {logging_mixin.py:137} INFO - [2023-05-13T20:13:20.686+0000] {dagbag.py:538} INFO - Filling up the DagBag from /opt/airflow/dags/gw2_dag.py
[2023-05-13T20:13:20.707+0000] {logging_mixin.py:137} INFO - [2023-05-13T20:13:20.706+0000] {dagbag.py:343} ERROR - Failed to import: /opt/airflow/dags/gw2_dag.py
Traceback (most recent call last):
  File "/home/airflow/.local/lib/python3.7/site-packages/airflow/models/dagbag.py", line 339, in parse
    loader.exec_module(new_module)
  File "<frozen importlib._bootstrap_external>", line 728, in exec_module
  File "<frozen importlib._bootstrap>", line 219, in _call_with_frames_removed
  File "/opt/airflow/dags/gw2_dag.py", line 20, in <module>
    from src.main_etl import gw2_etl
  File "/opt/airflow/plugins/src/main_etl.py", line 17, in <module>
    import pymongo
ModuleNotFoundError: No module named 'pymongo'
[2023-05-13T20:13:20.707+0000] {processor.py:755} WARNING - No viable dags retrieved from /opt/airflow/dags/gw2_dag.py
[2023-05-13T20:13:20.726+0000] {processor.py:175} INFO - Processing /opt/airflow/dags/gw2_dag.py took 0.045 seconds
[2023-05-13T20:13:50.905+0000] {processor.py:153} INFO - Started process (PID=2601) to work on /opt/airflow/dags/gw2_dag.py
[2023-05-13T20:13:50.908+0000] {processor.py:743} INFO - Processing file /opt/airflow/dags/gw2_dag.py for tasks to queue
[2023-05-13T20:13:50.908+0000] {logging_mixin.py:137} INFO - [2023-05-13T20:13:50.908+0000] {dagbag.py:538} INFO - Filling up the DagBag from /opt/airflow/dags/gw2_dag.py
[2023-05-13T20:13:50.922+0000] {logging_mixin.py:137} INFO - [2023-05-13T20:13:50.921+0000] {dagbag.py:343} ERROR - Failed to import: /opt/airflow/dags/gw2_dag.py
Traceback (most recent call last):
  File "/home/airflow/.local/lib/python3.7/site-packages/airflow/models/dagbag.py", line 339, in parse
    loader.exec_module(new_module)
  File "<frozen importlib._bootstrap_external>", line 728, in exec_module
  File "<frozen importlib._bootstrap>", line 219, in _call_with_frames_removed
  File "/opt/airflow/dags/gw2_dag.py", line 20, in <module>
    from src.main_etl import gw2_etl
  File "/opt/airflow/plugins/src/main_etl.py", line 17, in <module>
    import pymongo
ModuleNotFoundError: No module named 'pymongo'
[2023-05-13T20:13:50.922+0000] {processor.py:755} WARNING - No viable dags retrieved from /opt/airflow/dags/gw2_dag.py
[2023-05-13T20:13:50.940+0000] {processor.py:175} INFO - Processing /opt/airflow/dags/gw2_dag.py took 0.037 seconds
[2023-05-13T20:16:20.311+0000] {processor.py:153} INFO - Started process (PID=193) to work on /opt/airflow/dags/gw2_dag.py
[2023-05-13T20:16:20.312+0000] {processor.py:743} INFO - Processing file /opt/airflow/dags/gw2_dag.py for tasks to queue
[2023-05-13T20:16:20.312+0000] {logging_mixin.py:137} INFO - [2023-05-13T20:16:20.312+0000] {dagbag.py:538} INFO - Filling up the DagBag from /opt/airflow/dags/gw2_dag.py
[2023-05-13T20:16:21.033+0000] {logging_mixin.py:137} INFO - [2023-05-13T20:16:21.031+0000] {dagbag.py:343} ERROR - Failed to import: /opt/airflow/dags/gw2_dag.py
Traceback (most recent call last):
  File "/home/airflow/.local/lib/python3.7/site-packages/airflow/models/dagbag.py", line 339, in parse
    loader.exec_module(new_module)
  File "<frozen importlib._bootstrap_external>", line 728, in exec_module
  File "<frozen importlib._bootstrap>", line 219, in _call_with_frames_removed
  File "/opt/airflow/dags/gw2_dag.py", line 20, in <module>
    from src.main_etl import gw2_etl
  File "/opt/airflow/plugins/src/main_etl.py", line 24, in <module>
    logging.config.fileConfig("../config/logging.conf")
  File "/usr/local/lib/python3.7/logging/config.py", line 71, in fileConfig
    formatters = _create_formatters(cp)
  File "/usr/local/lib/python3.7/logging/config.py", line 104, in _create_formatters
    flist = cp["formatters"]["keys"]
  File "/usr/local/lib/python3.7/configparser.py", line 958, in __getitem__
    raise KeyError(key)
KeyError: 'formatters'
[2023-05-13T20:16:21.033+0000] {processor.py:755} WARNING - No viable dags retrieved from /opt/airflow/dags/gw2_dag.py
[2023-05-13T20:16:21.047+0000] {processor.py:175} INFO - Processing /opt/airflow/dags/gw2_dag.py took 0.738 seconds
[2023-05-13T20:16:51.321+0000] {processor.py:153} INFO - Started process (PID=427) to work on /opt/airflow/dags/gw2_dag.py
[2023-05-13T20:16:51.324+0000] {processor.py:743} INFO - Processing file /opt/airflow/dags/gw2_dag.py for tasks to queue
[2023-05-13T20:16:51.325+0000] {logging_mixin.py:137} INFO - [2023-05-13T20:16:51.325+0000] {dagbag.py:538} INFO - Filling up the DagBag from /opt/airflow/dags/gw2_dag.py
[2023-05-13T20:16:51.693+0000] {logging_mixin.py:137} INFO - [2023-05-13T20:16:51.692+0000] {dagbag.py:343} ERROR - Failed to import: /opt/airflow/dags/gw2_dag.py
Traceback (most recent call last):
  File "/home/airflow/.local/lib/python3.7/site-packages/airflow/models/dagbag.py", line 339, in parse
    loader.exec_module(new_module)
  File "<frozen importlib._bootstrap_external>", line 728, in exec_module
  File "<frozen importlib._bootstrap>", line 219, in _call_with_frames_removed
  File "/opt/airflow/dags/gw2_dag.py", line 20, in <module>
    from src.main_etl import gw2_etl
  File "/opt/airflow/plugins/src/main_etl.py", line 24, in <module>
    logging.config.fileConfig("../config/logging.conf")
  File "/usr/local/lib/python3.7/logging/config.py", line 71, in fileConfig
    formatters = _create_formatters(cp)
  File "/usr/local/lib/python3.7/logging/config.py", line 104, in _create_formatters
    flist = cp["formatters"]["keys"]
  File "/usr/local/lib/python3.7/configparser.py", line 958, in __getitem__
    raise KeyError(key)
KeyError: 'formatters'
[2023-05-13T20:16:51.694+0000] {processor.py:755} WARNING - No viable dags retrieved from /opt/airflow/dags/gw2_dag.py
[2023-05-13T20:16:51.709+0000] {processor.py:175} INFO - Processing /opt/airflow/dags/gw2_dag.py took 0.390 seconds
[2023-05-13T20:17:21.782+0000] {processor.py:153} INFO - Started process (PID=691) to work on /opt/airflow/dags/gw2_dag.py
[2023-05-13T20:17:21.783+0000] {processor.py:743} INFO - Processing file /opt/airflow/dags/gw2_dag.py for tasks to queue
[2023-05-13T20:17:21.784+0000] {logging_mixin.py:137} INFO - [2023-05-13T20:17:21.784+0000] {dagbag.py:538} INFO - Filling up the DagBag from /opt/airflow/dags/gw2_dag.py
[2023-05-13T20:17:22.146+0000] {logging_mixin.py:137} INFO - [2023-05-13T20:17:22.144+0000] {dagbag.py:343} ERROR - Failed to import: /opt/airflow/dags/gw2_dag.py
Traceback (most recent call last):
  File "/home/airflow/.local/lib/python3.7/site-packages/airflow/models/dagbag.py", line 339, in parse
    loader.exec_module(new_module)
  File "<frozen importlib._bootstrap_external>", line 728, in exec_module
  File "<frozen importlib._bootstrap>", line 219, in _call_with_frames_removed
  File "/opt/airflow/dags/gw2_dag.py", line 20, in <module>
    from src.main_etl import gw2_etl
  File "/opt/airflow/plugins/src/main_etl.py", line 24, in <module>
    logging.config.fileConfig("../config/logging.conf")
  File "/usr/local/lib/python3.7/logging/config.py", line 71, in fileConfig
    formatters = _create_formatters(cp)
  File "/usr/local/lib/python3.7/logging/config.py", line 104, in _create_formatters
    flist = cp["formatters"]["keys"]
  File "/usr/local/lib/python3.7/configparser.py", line 958, in __getitem__
    raise KeyError(key)
KeyError: 'formatters'
[2023-05-13T20:17:22.146+0000] {processor.py:755} WARNING - No viable dags retrieved from /opt/airflow/dags/gw2_dag.py
[2023-05-13T20:17:22.159+0000] {processor.py:175} INFO - Processing /opt/airflow/dags/gw2_dag.py took 0.379 seconds
[2023-05-13T20:17:52.988+0000] {processor.py:153} INFO - Started process (PID=934) to work on /opt/airflow/dags/gw2_dag.py
[2023-05-13T20:17:52.989+0000] {processor.py:743} INFO - Processing file /opt/airflow/dags/gw2_dag.py for tasks to queue
[2023-05-13T20:17:52.989+0000] {logging_mixin.py:137} INFO - [2023-05-13T20:17:52.989+0000] {dagbag.py:538} INFO - Filling up the DagBag from /opt/airflow/dags/gw2_dag.py
[2023-05-13T20:17:53.284+0000] {logging_mixin.py:137} INFO - [2023-05-13T20:17:53.283+0000] {dagbag.py:343} ERROR - Failed to import: /opt/airflow/dags/gw2_dag.py
Traceback (most recent call last):
  File "/home/airflow/.local/lib/python3.7/site-packages/airflow/models/dagbag.py", line 339, in parse
    loader.exec_module(new_module)
  File "<frozen importlib._bootstrap_external>", line 728, in exec_module
  File "<frozen importlib._bootstrap>", line 219, in _call_with_frames_removed
  File "/opt/airflow/dags/gw2_dag.py", line 20, in <module>
    from src.main_etl import gw2_etl
  File "/opt/airflow/plugins/src/main_etl.py", line 24, in <module>
    logging.config.fileConfig("../config/logging.conf")
  File "/usr/local/lib/python3.7/logging/config.py", line 71, in fileConfig
    formatters = _create_formatters(cp)
  File "/usr/local/lib/python3.7/logging/config.py", line 104, in _create_formatters
    flist = cp["formatters"]["keys"]
  File "/usr/local/lib/python3.7/configparser.py", line 958, in __getitem__
    raise KeyError(key)
KeyError: 'formatters'
[2023-05-13T20:17:53.284+0000] {processor.py:755} WARNING - No viable dags retrieved from /opt/airflow/dags/gw2_dag.py
[2023-05-13T20:17:53.295+0000] {processor.py:175} INFO - Processing /opt/airflow/dags/gw2_dag.py took 0.309 seconds
[2023-05-13T20:19:10.761+0000] {processor.py:153} INFO - Started process (PID=191) to work on /opt/airflow/dags/gw2_dag.py
[2023-05-13T20:19:10.762+0000] {processor.py:743} INFO - Processing file /opt/airflow/dags/gw2_dag.py for tasks to queue
[2023-05-13T20:19:10.762+0000] {logging_mixin.py:137} INFO - [2023-05-13T20:19:10.762+0000] {dagbag.py:538} INFO - Filling up the DagBag from /opt/airflow/dags/gw2_dag.py
[2023-05-13T20:19:10.811+0000] {logging_mixin.py:137} INFO - [2023-05-13T20:19:10.810+0000] {dagbag.py:343} ERROR - Failed to import: /opt/airflow/dags/gw2_dag.py
Traceback (most recent call last):
  File "/home/airflow/.local/lib/python3.7/site-packages/airflow/models/dagbag.py", line 339, in parse
    loader.exec_module(new_module)
  File "<frozen importlib._bootstrap_external>", line 728, in exec_module
  File "<frozen importlib._bootstrap>", line 219, in _call_with_frames_removed
  File "/opt/airflow/dags/gw2_dag.py", line 17, in <module>
    from src.url_writer import url_writer_script
ModuleNotFoundError: No module named 'src.url_writer'
[2023-05-13T20:19:10.812+0000] {processor.py:755} WARNING - No viable dags retrieved from /opt/airflow/dags/gw2_dag.py
[2023-05-13T20:19:10.831+0000] {processor.py:175} INFO - Processing /opt/airflow/dags/gw2_dag.py took 0.073 seconds
[2023-05-13T20:19:41.691+0000] {processor.py:153} INFO - Started process (PID=424) to work on /opt/airflow/dags/gw2_dag.py
[2023-05-13T20:19:41.693+0000] {processor.py:743} INFO - Processing file /opt/airflow/dags/gw2_dag.py for tasks to queue
[2023-05-13T20:19:41.694+0000] {logging_mixin.py:137} INFO - [2023-05-13T20:19:41.694+0000] {dagbag.py:538} INFO - Filling up the DagBag from /opt/airflow/dags/gw2_dag.py
[2023-05-13T20:19:41.713+0000] {logging_mixin.py:137} INFO - [2023-05-13T20:19:41.712+0000] {dagbag.py:343} ERROR - Failed to import: /opt/airflow/dags/gw2_dag.py
Traceback (most recent call last):
  File "/home/airflow/.local/lib/python3.7/site-packages/airflow/models/dagbag.py", line 339, in parse
    loader.exec_module(new_module)
  File "<frozen importlib._bootstrap_external>", line 728, in exec_module
  File "<frozen importlib._bootstrap>", line 219, in _call_with_frames_removed
  File "/opt/airflow/dags/gw2_dag.py", line 17, in <module>
    from src.url_writer import url_writer_script
ModuleNotFoundError: No module named 'src.url_writer'
[2023-05-13T20:19:41.714+0000] {processor.py:755} WARNING - No viable dags retrieved from /opt/airflow/dags/gw2_dag.py
[2023-05-13T20:19:41.735+0000] {processor.py:175} INFO - Processing /opt/airflow/dags/gw2_dag.py took 0.047 seconds
[2023-05-13T20:20:12.245+0000] {processor.py:153} INFO - Started process (PID=671) to work on /opt/airflow/dags/gw2_dag.py
[2023-05-13T20:20:12.245+0000] {processor.py:743} INFO - Processing file /opt/airflow/dags/gw2_dag.py for tasks to queue
[2023-05-13T20:20:12.246+0000] {logging_mixin.py:137} INFO - [2023-05-13T20:20:12.246+0000] {dagbag.py:538} INFO - Filling up the DagBag from /opt/airflow/dags/gw2_dag.py
[2023-05-13T20:20:12.260+0000] {logging_mixin.py:137} INFO - [2023-05-13T20:20:12.259+0000] {dagbag.py:343} ERROR - Failed to import: /opt/airflow/dags/gw2_dag.py
Traceback (most recent call last):
  File "/home/airflow/.local/lib/python3.7/site-packages/airflow/models/dagbag.py", line 339, in parse
    loader.exec_module(new_module)
  File "<frozen importlib._bootstrap_external>", line 728, in exec_module
  File "<frozen importlib._bootstrap>", line 219, in _call_with_frames_removed
  File "/opt/airflow/dags/gw2_dag.py", line 17, in <module>
    from src.url_writer import url_writer_script
ModuleNotFoundError: No module named 'src.url_writer'
[2023-05-13T20:20:12.260+0000] {processor.py:755} WARNING - No viable dags retrieved from /opt/airflow/dags/gw2_dag.py
[2023-05-13T20:20:12.277+0000] {processor.py:175} INFO - Processing /opt/airflow/dags/gw2_dag.py took 0.035 seconds
[2023-05-13T20:20:42.525+0000] {processor.py:153} INFO - Started process (PID=903) to work on /opt/airflow/dags/gw2_dag.py
[2023-05-13T20:20:42.526+0000] {processor.py:743} INFO - Processing file /opt/airflow/dags/gw2_dag.py for tasks to queue
[2023-05-13T20:20:42.527+0000] {logging_mixin.py:137} INFO - [2023-05-13T20:20:42.527+0000] {dagbag.py:538} INFO - Filling up the DagBag from /opt/airflow/dags/gw2_dag.py
[2023-05-13T20:20:42.544+0000] {logging_mixin.py:137} INFO - [2023-05-13T20:20:42.543+0000] {dagbag.py:343} ERROR - Failed to import: /opt/airflow/dags/gw2_dag.py
Traceback (most recent call last):
  File "/home/airflow/.local/lib/python3.7/site-packages/airflow/models/dagbag.py", line 339, in parse
    loader.exec_module(new_module)
  File "<frozen importlib._bootstrap_external>", line 728, in exec_module
  File "<frozen importlib._bootstrap>", line 219, in _call_with_frames_removed
  File "/opt/airflow/dags/gw2_dag.py", line 17, in <module>
    from src.url_writer import url_writer_script
ModuleNotFoundError: No module named 'src.url_writer'
[2023-05-13T20:20:42.545+0000] {processor.py:755} WARNING - No viable dags retrieved from /opt/airflow/dags/gw2_dag.py
[2023-05-13T20:20:42.564+0000] {processor.py:175} INFO - Processing /opt/airflow/dags/gw2_dag.py took 0.042 seconds
[2023-05-13T20:21:13.297+0000] {processor.py:153} INFO - Started process (PID=1152) to work on /opt/airflow/dags/gw2_dag.py
[2023-05-13T20:21:13.300+0000] {processor.py:743} INFO - Processing file /opt/airflow/dags/gw2_dag.py for tasks to queue
[2023-05-13T20:21:13.301+0000] {logging_mixin.py:137} INFO - [2023-05-13T20:21:13.300+0000] {dagbag.py:538} INFO - Filling up the DagBag from /opt/airflow/dags/gw2_dag.py
[2023-05-13T20:21:13.319+0000] {logging_mixin.py:137} INFO - [2023-05-13T20:21:13.318+0000] {dagbag.py:343} ERROR - Failed to import: /opt/airflow/dags/gw2_dag.py
Traceback (most recent call last):
  File "/home/airflow/.local/lib/python3.7/site-packages/airflow/models/dagbag.py", line 339, in parse
    loader.exec_module(new_module)
  File "<frozen importlib._bootstrap_external>", line 728, in exec_module
  File "<frozen importlib._bootstrap>", line 219, in _call_with_frames_removed
  File "/opt/airflow/dags/gw2_dag.py", line 17, in <module>
    from src.url_writer import url_writer_script
ModuleNotFoundError: No module named 'src.url_writer'
[2023-05-13T20:21:13.319+0000] {processor.py:755} WARNING - No viable dags retrieved from /opt/airflow/dags/gw2_dag.py
[2023-05-13T20:21:13.341+0000] {processor.py:175} INFO - Processing /opt/airflow/dags/gw2_dag.py took 0.046 seconds
[2023-05-13T20:21:43.473+0000] {processor.py:153} INFO - Started process (PID=1384) to work on /opt/airflow/dags/gw2_dag.py
[2023-05-13T20:21:43.476+0000] {processor.py:743} INFO - Processing file /opt/airflow/dags/gw2_dag.py for tasks to queue
[2023-05-13T20:21:43.477+0000] {logging_mixin.py:137} INFO - [2023-05-13T20:21:43.476+0000] {dagbag.py:538} INFO - Filling up the DagBag from /opt/airflow/dags/gw2_dag.py
[2023-05-13T20:21:43.490+0000] {logging_mixin.py:137} INFO - [2023-05-13T20:21:43.489+0000] {dagbag.py:343} ERROR - Failed to import: /opt/airflow/dags/gw2_dag.py
Traceback (most recent call last):
  File "/home/airflow/.local/lib/python3.7/site-packages/airflow/models/dagbag.py", line 339, in parse
    loader.exec_module(new_module)
  File "<frozen importlib._bootstrap_external>", line 728, in exec_module
  File "<frozen importlib._bootstrap>", line 219, in _call_with_frames_removed
  File "/opt/airflow/dags/gw2_dag.py", line 17, in <module>
    from src.url_writer import url_writer_script
ModuleNotFoundError: No module named 'src.url_writer'
[2023-05-13T20:21:43.490+0000] {processor.py:755} WARNING - No viable dags retrieved from /opt/airflow/dags/gw2_dag.py
[2023-05-13T20:21:43.510+0000] {processor.py:175} INFO - Processing /opt/airflow/dags/gw2_dag.py took 0.039 seconds
[2023-05-13T20:22:14.076+0000] {processor.py:153} INFO - Started process (PID=1632) to work on /opt/airflow/dags/gw2_dag.py
[2023-05-13T20:22:14.079+0000] {processor.py:743} INFO - Processing file /opt/airflow/dags/gw2_dag.py for tasks to queue
[2023-05-13T20:22:14.079+0000] {logging_mixin.py:137} INFO - [2023-05-13T20:22:14.079+0000] {dagbag.py:538} INFO - Filling up the DagBag from /opt/airflow/dags/gw2_dag.py
[2023-05-13T20:22:14.092+0000] {logging_mixin.py:137} INFO - [2023-05-13T20:22:14.092+0000] {dagbag.py:343} ERROR - Failed to import: /opt/airflow/dags/gw2_dag.py
Traceback (most recent call last):
  File "/home/airflow/.local/lib/python3.7/site-packages/airflow/models/dagbag.py", line 339, in parse
    loader.exec_module(new_module)
  File "<frozen importlib._bootstrap_external>", line 728, in exec_module
  File "<frozen importlib._bootstrap>", line 219, in _call_with_frames_removed
  File "/opt/airflow/dags/gw2_dag.py", line 17, in <module>
    from src.url_writer import url_writer_script
ModuleNotFoundError: No module named 'src.url_writer'
[2023-05-13T20:22:14.093+0000] {processor.py:755} WARNING - No viable dags retrieved from /opt/airflow/dags/gw2_dag.py
[2023-05-13T20:22:14.110+0000] {processor.py:175} INFO - Processing /opt/airflow/dags/gw2_dag.py took 0.036 seconds
[2023-05-13T20:22:43.071+0000] {processor.py:153} INFO - Started process (PID=1864) to work on /opt/airflow/dags/gw2_dag.py
[2023-05-13T20:22:43.071+0000] {processor.py:743} INFO - Processing file /opt/airflow/dags/gw2_dag.py for tasks to queue
[2023-05-13T20:22:43.072+0000] {logging_mixin.py:137} INFO - [2023-05-13T20:22:43.072+0000] {dagbag.py:538} INFO - Filling up the DagBag from /opt/airflow/dags/gw2_dag.py
[2023-05-13T20:22:43.086+0000] {logging_mixin.py:137} INFO - [2023-05-13T20:22:43.085+0000] {dagbag.py:343} ERROR - Failed to import: /opt/airflow/dags/gw2_dag.py
Traceback (most recent call last):
  File "/home/airflow/.local/lib/python3.7/site-packages/airflow/models/dagbag.py", line 339, in parse
    loader.exec_module(new_module)
  File "<frozen importlib._bootstrap_external>", line 728, in exec_module
  File "<frozen importlib._bootstrap>", line 219, in _call_with_frames_removed
  File "/opt/airflow/dags/gw2_dag.py", line 17, in <module>
    from src.url_writer import url_writer_script
ModuleNotFoundError: No module named 'src.url_writer'
[2023-05-13T20:22:43.086+0000] {processor.py:755} WARNING - No viable dags retrieved from /opt/airflow/dags/gw2_dag.py
[2023-05-13T20:22:43.104+0000] {processor.py:175} INFO - Processing /opt/airflow/dags/gw2_dag.py took 0.035 seconds
[2023-05-13T20:23:13.876+0000] {processor.py:153} INFO - Started process (PID=2113) to work on /opt/airflow/dags/gw2_dag.py
[2023-05-13T20:23:13.878+0000] {processor.py:743} INFO - Processing file /opt/airflow/dags/gw2_dag.py for tasks to queue
[2023-05-13T20:23:13.879+0000] {logging_mixin.py:137} INFO - [2023-05-13T20:23:13.879+0000] {dagbag.py:538} INFO - Filling up the DagBag from /opt/airflow/dags/gw2_dag.py
[2023-05-13T20:23:13.889+0000] {logging_mixin.py:137} INFO - [2023-05-13T20:23:13.888+0000] {dagbag.py:343} ERROR - Failed to import: /opt/airflow/dags/gw2_dag.py
Traceback (most recent call last):
  File "/home/airflow/.local/lib/python3.7/site-packages/airflow/models/dagbag.py", line 339, in parse
    loader.exec_module(new_module)
  File "<frozen importlib._bootstrap_external>", line 728, in exec_module
  File "<frozen importlib._bootstrap>", line 219, in _call_with_frames_removed
  File "/opt/airflow/dags/gw2_dag.py", line 17, in <module>
    from src.url_writer import url_writer_script
ModuleNotFoundError: No module named 'src.url_writer'
[2023-05-13T20:23:13.889+0000] {processor.py:755} WARNING - No viable dags retrieved from /opt/airflow/dags/gw2_dag.py
[2023-05-13T20:23:13.901+0000] {processor.py:175} INFO - Processing /opt/airflow/dags/gw2_dag.py took 0.028 seconds
[2023-05-13T20:23:19.543+0000] {processor.py:153} INFO - Started process (PID=2313) to work on /opt/airflow/dags/gw2_dag.py
[2023-05-13T20:23:19.544+0000] {processor.py:743} INFO - Processing file /opt/airflow/dags/gw2_dag.py for tasks to queue
[2023-05-13T20:23:19.544+0000] {logging_mixin.py:137} INFO - [2023-05-13T20:23:19.544+0000] {dagbag.py:538} INFO - Filling up the DagBag from /opt/airflow/dags/gw2_dag.py
[2023-05-13T20:23:19.560+0000] {logging_mixin.py:137} INFO - [2023-05-13T20:23:19.559+0000] {dagbag.py:343} ERROR - Failed to import: /opt/airflow/dags/gw2_dag.py
Traceback (most recent call last):
  File "/home/airflow/.local/lib/python3.7/site-packages/airflow/models/dagbag.py", line 339, in parse
    loader.exec_module(new_module)
  File "<frozen importlib._bootstrap_external>", line 728, in exec_module
  File "<frozen importlib._bootstrap>", line 219, in _call_with_frames_removed
  File "/opt/airflow/dags/gw2_dag.py", line 17, in <module>
    from src.url_writer import url_writer_script
ModuleNotFoundError: No module named 'src.url_writer'
[2023-05-13T20:23:19.560+0000] {processor.py:755} WARNING - No viable dags retrieved from /opt/airflow/dags/gw2_dag.py
[2023-05-13T20:23:19.576+0000] {processor.py:175} INFO - Processing /opt/airflow/dags/gw2_dag.py took 0.036 seconds
[2023-05-13T20:23:50.400+0000] {processor.py:153} INFO - Started process (PID=2561) to work on /opt/airflow/dags/gw2_dag.py
[2023-05-13T20:23:50.403+0000] {processor.py:743} INFO - Processing file /opt/airflow/dags/gw2_dag.py for tasks to queue
[2023-05-13T20:23:50.403+0000] {logging_mixin.py:137} INFO - [2023-05-13T20:23:50.403+0000] {dagbag.py:538} INFO - Filling up the DagBag from /opt/airflow/dags/gw2_dag.py
[2023-05-13T20:23:50.413+0000] {logging_mixin.py:137} INFO - [2023-05-13T20:23:50.413+0000] {dagbag.py:343} ERROR - Failed to import: /opt/airflow/dags/gw2_dag.py
Traceback (most recent call last):
  File "/home/airflow/.local/lib/python3.7/site-packages/airflow/models/dagbag.py", line 339, in parse
    loader.exec_module(new_module)
  File "<frozen importlib._bootstrap_external>", line 728, in exec_module
  File "<frozen importlib._bootstrap>", line 219, in _call_with_frames_removed
  File "/opt/airflow/dags/gw2_dag.py", line 17, in <module>
    from src.url_writer import url_writer_script
ModuleNotFoundError: No module named 'src.url_writer'
[2023-05-13T20:23:50.414+0000] {processor.py:755} WARNING - No viable dags retrieved from /opt/airflow/dags/gw2_dag.py
[2023-05-13T20:23:50.426+0000] {processor.py:175} INFO - Processing /opt/airflow/dags/gw2_dag.py took 0.027 seconds
[2023-05-13T20:23:52.426+0000] {processor.py:153} INFO - Started process (PID=2566) to work on /opt/airflow/dags/gw2_dag.py
[2023-05-13T20:23:52.426+0000] {processor.py:743} INFO - Processing file /opt/airflow/dags/gw2_dag.py for tasks to queue
[2023-05-13T20:23:52.427+0000] {logging_mixin.py:137} INFO - [2023-05-13T20:23:52.427+0000] {dagbag.py:538} INFO - Filling up the DagBag from /opt/airflow/dags/gw2_dag.py
[2023-05-13T20:23:52.436+0000] {logging_mixin.py:137} INFO - [2023-05-13T20:23:52.436+0000] {dagbag.py:343} ERROR - Failed to import: /opt/airflow/dags/gw2_dag.py
Traceback (most recent call last):
  File "/home/airflow/.local/lib/python3.7/site-packages/airflow/models/dagbag.py", line 339, in parse
    loader.exec_module(new_module)
  File "<frozen importlib._bootstrap_external>", line 728, in exec_module
  File "<frozen importlib._bootstrap>", line 219, in _call_with_frames_removed
  File "/opt/airflow/dags/gw2_dag.py", line 17, in <module>
    from src.url_writer import url_writer_script
ModuleNotFoundError: No module named 'src.url_writer'
[2023-05-13T20:23:52.436+0000] {processor.py:755} WARNING - No viable dags retrieved from /opt/airflow/dags/gw2_dag.py
[2023-05-13T20:23:52.448+0000] {processor.py:175} INFO - Processing /opt/airflow/dags/gw2_dag.py took 0.024 seconds
[2023-05-13T20:24:22.880+0000] {processor.py:153} INFO - Started process (PID=2814) to work on /opt/airflow/dags/gw2_dag.py
[2023-05-13T20:24:22.881+0000] {processor.py:743} INFO - Processing file /opt/airflow/dags/gw2_dag.py for tasks to queue
[2023-05-13T20:24:22.882+0000] {logging_mixin.py:137} INFO - [2023-05-13T20:24:22.882+0000] {dagbag.py:538} INFO - Filling up the DagBag from /opt/airflow/dags/gw2_dag.py
[2023-05-13T20:24:22.900+0000] {logging_mixin.py:137} INFO - [2023-05-13T20:24:22.898+0000] {dagbag.py:343} ERROR - Failed to import: /opt/airflow/dags/gw2_dag.py
Traceback (most recent call last):
  File "/home/airflow/.local/lib/python3.7/site-packages/airflow/models/dagbag.py", line 339, in parse
    loader.exec_module(new_module)
  File "<frozen importlib._bootstrap_external>", line 728, in exec_module
  File "<frozen importlib._bootstrap>", line 219, in _call_with_frames_removed
  File "/opt/airflow/dags/gw2_dag.py", line 17, in <module>
    from src.url_writer import url_writer_script
ModuleNotFoundError: No module named 'src.url_writer'
[2023-05-13T20:24:22.900+0000] {processor.py:755} WARNING - No viable dags retrieved from /opt/airflow/dags/gw2_dag.py
[2023-05-13T20:24:22.913+0000] {processor.py:175} INFO - Processing /opt/airflow/dags/gw2_dag.py took 0.035 seconds
[2023-05-13T20:24:50.992+0000] {processor.py:153} INFO - Started process (PID=3047) to work on /opt/airflow/dags/gw2_dag.py
[2023-05-13T20:24:50.995+0000] {processor.py:743} INFO - Processing file /opt/airflow/dags/gw2_dag.py for tasks to queue
[2023-05-13T20:24:50.995+0000] {logging_mixin.py:137} INFO - [2023-05-13T20:24:50.995+0000] {dagbag.py:538} INFO - Filling up the DagBag from /opt/airflow/dags/gw2_dag.py
[2023-05-13T20:24:51.010+0000] {logging_mixin.py:137} INFO - [2023-05-13T20:24:51.009+0000] {dagbag.py:343} ERROR - Failed to import: /opt/airflow/dags/gw2_dag.py
Traceback (most recent call last):
  File "/home/airflow/.local/lib/python3.7/site-packages/airflow/models/dagbag.py", line 339, in parse
    loader.exec_module(new_module)
  File "<frozen importlib._bootstrap_external>", line 728, in exec_module
  File "<frozen importlib._bootstrap>", line 219, in _call_with_frames_removed
  File "/opt/airflow/dags/gw2_dag.py", line 17, in <module>
    from src.url_writer import url_writer_script
ModuleNotFoundError: No module named 'src.url_writer'
[2023-05-13T20:24:51.010+0000] {processor.py:755} WARNING - No viable dags retrieved from /opt/airflow/dags/gw2_dag.py
[2023-05-13T20:24:51.028+0000] {processor.py:175} INFO - Processing /opt/airflow/dags/gw2_dag.py took 0.038 seconds
[2023-05-13T20:24:59.038+0000] {processor.py:153} INFO - Started process (PID=3068) to work on /opt/airflow/dags/gw2_dag.py
[2023-05-13T20:24:59.041+0000] {processor.py:743} INFO - Processing file /opt/airflow/dags/gw2_dag.py for tasks to queue
[2023-05-13T20:24:59.042+0000] {logging_mixin.py:137} INFO - [2023-05-13T20:24:59.042+0000] {dagbag.py:538} INFO - Filling up the DagBag from /opt/airflow/dags/gw2_dag.py
[2023-05-13T20:24:59.061+0000] {logging_mixin.py:137} INFO - [2023-05-13T20:24:59.060+0000] {dagbag.py:343} ERROR - Failed to import: /opt/airflow/dags/gw2_dag.py
Traceback (most recent call last):
  File "/home/airflow/.local/lib/python3.7/site-packages/airflow/models/dagbag.py", line 339, in parse
    loader.exec_module(new_module)
  File "<frozen importlib._bootstrap_external>", line 728, in exec_module
  File "<frozen importlib._bootstrap>", line 219, in _call_with_frames_removed
  File "/opt/airflow/dags/gw2_dag.py", line 17, in <module>
    from src.url_writer import url_writer_script
ModuleNotFoundError: No module named 'src.url_writer'
[2023-05-13T20:24:59.061+0000] {processor.py:755} WARNING - No viable dags retrieved from /opt/airflow/dags/gw2_dag.py
[2023-05-13T20:24:59.083+0000] {processor.py:175} INFO - Processing /opt/airflow/dags/gw2_dag.py took 0.049 seconds
[2023-05-13T20:25:18.376+0000] {processor.py:153} INFO - Started process (PID=3104) to work on /opt/airflow/dags/gw2_dag.py
[2023-05-13T20:25:18.377+0000] {processor.py:743} INFO - Processing file /opt/airflow/dags/gw2_dag.py for tasks to queue
[2023-05-13T20:25:18.378+0000] {logging_mixin.py:137} INFO - [2023-05-13T20:25:18.378+0000] {dagbag.py:538} INFO - Filling up the DagBag from /opt/airflow/dags/gw2_dag.py
[2023-05-13T20:25:18.398+0000] {logging_mixin.py:137} INFO - [2023-05-13T20:25:18.397+0000] {dagbag.py:343} ERROR - Failed to import: /opt/airflow/dags/gw2_dag.py
Traceback (most recent call last):
  File "/home/airflow/.local/lib/python3.7/site-packages/airflow/models/dagbag.py", line 339, in parse
    loader.exec_module(new_module)
  File "<frozen importlib._bootstrap_external>", line 728, in exec_module
  File "<frozen importlib._bootstrap>", line 219, in _call_with_frames_removed
  File "/opt/airflow/dags/gw2_dag.py", line 17, in <module>
    from src.url_writer import url_writer_script
ModuleNotFoundError: No module named 'src.url_writer'
[2023-05-13T20:25:18.398+0000] {processor.py:755} WARNING - No viable dags retrieved from /opt/airflow/dags/gw2_dag.py
[2023-05-13T20:25:18.422+0000] {processor.py:175} INFO - Processing /opt/airflow/dags/gw2_dag.py took 0.049 seconds
[2023-05-13T20:25:48.542+0000] {processor.py:153} INFO - Started process (PID=3337) to work on /opt/airflow/dags/gw2_dag.py
[2023-05-13T20:25:48.545+0000] {processor.py:743} INFO - Processing file /opt/airflow/dags/gw2_dag.py for tasks to queue
[2023-05-13T20:25:48.545+0000] {logging_mixin.py:137} INFO - [2023-05-13T20:25:48.545+0000] {dagbag.py:538} INFO - Filling up the DagBag from /opt/airflow/dags/gw2_dag.py
[2023-05-13T20:25:48.555+0000] {logging_mixin.py:137} INFO - [2023-05-13T20:25:48.555+0000] {dagbag.py:343} ERROR - Failed to import: /opt/airflow/dags/gw2_dag.py
Traceback (most recent call last):
  File "/home/airflow/.local/lib/python3.7/site-packages/airflow/models/dagbag.py", line 339, in parse
    loader.exec_module(new_module)
  File "<frozen importlib._bootstrap_external>", line 728, in exec_module
  File "<frozen importlib._bootstrap>", line 219, in _call_with_frames_removed
  File "/opt/airflow/dags/gw2_dag.py", line 17, in <module>
    from src.url_writer import url_writer_script
ModuleNotFoundError: No module named 'src.url_writer'
[2023-05-13T20:25:48.555+0000] {processor.py:755} WARNING - No viable dags retrieved from /opt/airflow/dags/gw2_dag.py
[2023-05-13T20:25:48.569+0000] {processor.py:175} INFO - Processing /opt/airflow/dags/gw2_dag.py took 0.028 seconds
[2023-05-13T20:26:18.698+0000] {processor.py:153} INFO - Started process (PID=3569) to work on /opt/airflow/dags/gw2_dag.py
[2023-05-13T20:26:18.700+0000] {processor.py:743} INFO - Processing file /opt/airflow/dags/gw2_dag.py for tasks to queue
[2023-05-13T20:26:18.701+0000] {logging_mixin.py:137} INFO - [2023-05-13T20:26:18.701+0000] {dagbag.py:538} INFO - Filling up the DagBag from /opt/airflow/dags/gw2_dag.py
[2023-05-13T20:26:18.714+0000] {logging_mixin.py:137} INFO - [2023-05-13T20:26:18.713+0000] {dagbag.py:343} ERROR - Failed to import: /opt/airflow/dags/gw2_dag.py
Traceback (most recent call last):
  File "/home/airflow/.local/lib/python3.7/site-packages/airflow/models/dagbag.py", line 339, in parse
    loader.exec_module(new_module)
  File "<frozen importlib._bootstrap_external>", line 728, in exec_module
  File "<frozen importlib._bootstrap>", line 219, in _call_with_frames_removed
  File "/opt/airflow/dags/gw2_dag.py", line 17, in <module>
    from src.url_writer import url_writer_script
ModuleNotFoundError: No module named 'src.url_writer'
[2023-05-13T20:26:18.714+0000] {processor.py:755} WARNING - No viable dags retrieved from /opt/airflow/dags/gw2_dag.py
[2023-05-13T20:26:18.731+0000] {processor.py:175} INFO - Processing /opt/airflow/dags/gw2_dag.py took 0.036 seconds
[2023-05-13T20:26:48.894+0000] {processor.py:153} INFO - Started process (PID=3817) to work on /opt/airflow/dags/gw2_dag.py
[2023-05-13T20:26:48.896+0000] {processor.py:743} INFO - Processing file /opt/airflow/dags/gw2_dag.py for tasks to queue
[2023-05-13T20:26:48.897+0000] {logging_mixin.py:137} INFO - [2023-05-13T20:26:48.897+0000] {dagbag.py:538} INFO - Filling up the DagBag from /opt/airflow/dags/gw2_dag.py
[2023-05-13T20:26:48.907+0000] {logging_mixin.py:137} INFO - [2023-05-13T20:26:48.906+0000] {dagbag.py:343} ERROR - Failed to import: /opt/airflow/dags/gw2_dag.py
Traceback (most recent call last):
  File "/home/airflow/.local/lib/python3.7/site-packages/airflow/models/dagbag.py", line 339, in parse
    loader.exec_module(new_module)
  File "<frozen importlib._bootstrap_external>", line 728, in exec_module
  File "<frozen importlib._bootstrap>", line 219, in _call_with_frames_removed
  File "/opt/airflow/dags/gw2_dag.py", line 17, in <module>
    from src.url_writer import url_writer_script
ModuleNotFoundError: No module named 'src.url_writer'
[2023-05-13T20:26:48.907+0000] {processor.py:755} WARNING - No viable dags retrieved from /opt/airflow/dags/gw2_dag.py
[2023-05-13T20:26:48.920+0000] {processor.py:175} INFO - Processing /opt/airflow/dags/gw2_dag.py took 0.028 seconds
[2023-05-13T20:27:19.103+0000] {processor.py:153} INFO - Started process (PID=4048) to work on /opt/airflow/dags/gw2_dag.py
[2023-05-13T20:27:19.106+0000] {processor.py:743} INFO - Processing file /opt/airflow/dags/gw2_dag.py for tasks to queue
[2023-05-13T20:27:19.107+0000] {logging_mixin.py:137} INFO - [2023-05-13T20:27:19.107+0000] {dagbag.py:538} INFO - Filling up the DagBag from /opt/airflow/dags/gw2_dag.py
[2023-05-13T20:27:19.119+0000] {logging_mixin.py:137} INFO - [2023-05-13T20:27:19.119+0000] {dagbag.py:343} ERROR - Failed to import: /opt/airflow/dags/gw2_dag.py
Traceback (most recent call last):
  File "/home/airflow/.local/lib/python3.7/site-packages/airflow/models/dagbag.py", line 339, in parse
    loader.exec_module(new_module)
  File "<frozen importlib._bootstrap_external>", line 728, in exec_module
  File "<frozen importlib._bootstrap>", line 219, in _call_with_frames_removed
  File "/opt/airflow/dags/gw2_dag.py", line 17, in <module>
    from src.url_writer import url_writer_script
ModuleNotFoundError: No module named 'src.url_writer'
[2023-05-13T20:27:19.120+0000] {processor.py:755} WARNING - No viable dags retrieved from /opt/airflow/dags/gw2_dag.py
[2023-05-13T20:27:19.137+0000] {processor.py:175} INFO - Processing /opt/airflow/dags/gw2_dag.py took 0.036 seconds
[2023-05-13T20:27:49.340+0000] {processor.py:153} INFO - Started process (PID=4296) to work on /opt/airflow/dags/gw2_dag.py
[2023-05-13T20:27:49.342+0000] {processor.py:743} INFO - Processing file /opt/airflow/dags/gw2_dag.py for tasks to queue
[2023-05-13T20:27:49.343+0000] {logging_mixin.py:137} INFO - [2023-05-13T20:27:49.343+0000] {dagbag.py:538} INFO - Filling up the DagBag from /opt/airflow/dags/gw2_dag.py
[2023-05-13T20:27:49.352+0000] {logging_mixin.py:137} INFO - [2023-05-13T20:27:49.352+0000] {dagbag.py:343} ERROR - Failed to import: /opt/airflow/dags/gw2_dag.py
Traceback (most recent call last):
  File "/home/airflow/.local/lib/python3.7/site-packages/airflow/models/dagbag.py", line 339, in parse
    loader.exec_module(new_module)
  File "<frozen importlib._bootstrap_external>", line 728, in exec_module
  File "<frozen importlib._bootstrap>", line 219, in _call_with_frames_removed
  File "/opt/airflow/dags/gw2_dag.py", line 17, in <module>
    from src.url_writer import url_writer_script
ModuleNotFoundError: No module named 'src.url_writer'
[2023-05-13T20:27:49.352+0000] {processor.py:755} WARNING - No viable dags retrieved from /opt/airflow/dags/gw2_dag.py
[2023-05-13T20:27:49.365+0000] {processor.py:175} INFO - Processing /opt/airflow/dags/gw2_dag.py took 0.027 seconds
[2023-05-13T20:28:19.995+0000] {processor.py:153} INFO - Started process (PID=4528) to work on /opt/airflow/dags/gw2_dag.py
[2023-05-13T20:28:19.996+0000] {processor.py:743} INFO - Processing file /opt/airflow/dags/gw2_dag.py for tasks to queue
[2023-05-13T20:28:19.996+0000] {logging_mixin.py:137} INFO - [2023-05-13T20:28:19.996+0000] {dagbag.py:538} INFO - Filling up the DagBag from /opt/airflow/dags/gw2_dag.py
[2023-05-13T20:28:20.009+0000] {logging_mixin.py:137} INFO - [2023-05-13T20:28:20.008+0000] {dagbag.py:343} ERROR - Failed to import: /opt/airflow/dags/gw2_dag.py
Traceback (most recent call last):
  File "/home/airflow/.local/lib/python3.7/site-packages/airflow/models/dagbag.py", line 339, in parse
    loader.exec_module(new_module)
  File "<frozen importlib._bootstrap_external>", line 728, in exec_module
  File "<frozen importlib._bootstrap>", line 219, in _call_with_frames_removed
  File "/opt/airflow/dags/gw2_dag.py", line 17, in <module>
    from src.url_writer import url_writer_script
ModuleNotFoundError: No module named 'src.url_writer'
[2023-05-13T20:28:20.009+0000] {processor.py:755} WARNING - No viable dags retrieved from /opt/airflow/dags/gw2_dag.py
[2023-05-13T20:28:20.026+0000] {processor.py:175} INFO - Processing /opt/airflow/dags/gw2_dag.py took 0.034 seconds
[2023-05-13T20:28:50.653+0000] {processor.py:153} INFO - Started process (PID=4776) to work on /opt/airflow/dags/gw2_dag.py
[2023-05-13T20:28:50.654+0000] {processor.py:743} INFO - Processing file /opt/airflow/dags/gw2_dag.py for tasks to queue
[2023-05-13T20:28:50.654+0000] {logging_mixin.py:137} INFO - [2023-05-13T20:28:50.654+0000] {dagbag.py:538} INFO - Filling up the DagBag from /opt/airflow/dags/gw2_dag.py
[2023-05-13T20:28:50.664+0000] {logging_mixin.py:137} INFO - [2023-05-13T20:28:50.664+0000] {dagbag.py:343} ERROR - Failed to import: /opt/airflow/dags/gw2_dag.py
Traceback (most recent call last):
  File "/home/airflow/.local/lib/python3.7/site-packages/airflow/models/dagbag.py", line 339, in parse
    loader.exec_module(new_module)
  File "<frozen importlib._bootstrap_external>", line 728, in exec_module
  File "<frozen importlib._bootstrap>", line 219, in _call_with_frames_removed
  File "/opt/airflow/dags/gw2_dag.py", line 17, in <module>
    from src.url_writer import url_writer_script
ModuleNotFoundError: No module named 'src.url_writer'
[2023-05-13T20:28:50.665+0000] {processor.py:755} WARNING - No viable dags retrieved from /opt/airflow/dags/gw2_dag.py
[2023-05-13T20:28:50.678+0000] {processor.py:175} INFO - Processing /opt/airflow/dags/gw2_dag.py took 0.026 seconds
[2023-05-13T20:29:21.017+0000] {processor.py:153} INFO - Started process (PID=5008) to work on /opt/airflow/dags/gw2_dag.py
[2023-05-13T20:29:21.017+0000] {processor.py:743} INFO - Processing file /opt/airflow/dags/gw2_dag.py for tasks to queue
[2023-05-13T20:29:21.018+0000] {logging_mixin.py:137} INFO - [2023-05-13T20:29:21.017+0000] {dagbag.py:538} INFO - Filling up the DagBag from /opt/airflow/dags/gw2_dag.py
[2023-05-13T20:29:21.031+0000] {logging_mixin.py:137} INFO - [2023-05-13T20:29:21.030+0000] {dagbag.py:343} ERROR - Failed to import: /opt/airflow/dags/gw2_dag.py
Traceback (most recent call last):
  File "/home/airflow/.local/lib/python3.7/site-packages/airflow/models/dagbag.py", line 339, in parse
    loader.exec_module(new_module)
  File "<frozen importlib._bootstrap_external>", line 728, in exec_module
  File "<frozen importlib._bootstrap>", line 219, in _call_with_frames_removed
  File "/opt/airflow/dags/gw2_dag.py", line 17, in <module>
    from src.url_writer import url_writer_script
ModuleNotFoundError: No module named 'src.url_writer'
[2023-05-13T20:29:21.031+0000] {processor.py:755} WARNING - No viable dags retrieved from /opt/airflow/dags/gw2_dag.py
[2023-05-13T20:29:21.048+0000] {processor.py:175} INFO - Processing /opt/airflow/dags/gw2_dag.py took 0.034 seconds
[2023-05-13T20:29:51.883+0000] {processor.py:153} INFO - Started process (PID=5255) to work on /opt/airflow/dags/gw2_dag.py
[2023-05-13T20:29:51.885+0000] {processor.py:743} INFO - Processing file /opt/airflow/dags/gw2_dag.py for tasks to queue
[2023-05-13T20:29:51.886+0000] {logging_mixin.py:137} INFO - [2023-05-13T20:29:51.886+0000] {dagbag.py:538} INFO - Filling up the DagBag from /opt/airflow/dags/gw2_dag.py
[2023-05-13T20:29:51.899+0000] {logging_mixin.py:137} INFO - [2023-05-13T20:29:51.898+0000] {dagbag.py:343} ERROR - Failed to import: /opt/airflow/dags/gw2_dag.py
Traceback (most recent call last):
  File "/home/airflow/.local/lib/python3.7/site-packages/airflow/models/dagbag.py", line 339, in parse
    loader.exec_module(new_module)
  File "<frozen importlib._bootstrap_external>", line 728, in exec_module
  File "<frozen importlib._bootstrap>", line 219, in _call_with_frames_removed
  File "/opt/airflow/dags/gw2_dag.py", line 17, in <module>
    from src.url_writer import url_writer_script
ModuleNotFoundError: No module named 'src.url_writer'
[2023-05-13T20:29:51.899+0000] {processor.py:755} WARNING - No viable dags retrieved from /opt/airflow/dags/gw2_dag.py
[2023-05-13T20:29:51.916+0000] {processor.py:175} INFO - Processing /opt/airflow/dags/gw2_dag.py took 0.036 seconds
[2023-05-13T20:30:22.218+0000] {processor.py:153} INFO - Started process (PID=5503) to work on /opt/airflow/dags/gw2_dag.py
[2023-05-13T20:30:22.219+0000] {processor.py:743} INFO - Processing file /opt/airflow/dags/gw2_dag.py for tasks to queue
[2023-05-13T20:30:22.219+0000] {logging_mixin.py:137} INFO - [2023-05-13T20:30:22.219+0000] {dagbag.py:538} INFO - Filling up the DagBag from /opt/airflow/dags/gw2_dag.py
[2023-05-13T20:30:22.231+0000] {logging_mixin.py:137} INFO - [2023-05-13T20:30:22.230+0000] {dagbag.py:343} ERROR - Failed to import: /opt/airflow/dags/gw2_dag.py
Traceback (most recent call last):
  File "/home/airflow/.local/lib/python3.7/site-packages/airflow/models/dagbag.py", line 339, in parse
    loader.exec_module(new_module)
  File "<frozen importlib._bootstrap_external>", line 728, in exec_module
  File "<frozen importlib._bootstrap>", line 219, in _call_with_frames_removed
  File "/opt/airflow/dags/gw2_dag.py", line 17, in <module>
    from src.url_writer import url_writer_script
ModuleNotFoundError: No module named 'src.url_writer'
[2023-05-13T20:30:22.231+0000] {processor.py:755} WARNING - No viable dags retrieved from /opt/airflow/dags/gw2_dag.py
[2023-05-13T20:30:22.245+0000] {processor.py:175} INFO - Processing /opt/airflow/dags/gw2_dag.py took 0.029 seconds
[2023-05-13T20:30:26.244+0000] {processor.py:153} INFO - Started process (PID=5703) to work on /opt/airflow/dags/gw2_dag.py
[2023-05-13T20:30:26.246+0000] {processor.py:743} INFO - Processing file /opt/airflow/dags/gw2_dag.py for tasks to queue
[2023-05-13T20:30:26.246+0000] {logging_mixin.py:137} INFO - [2023-05-13T20:30:26.246+0000] {dagbag.py:538} INFO - Filling up the DagBag from /opt/airflow/dags/gw2_dag.py
[2023-05-13T20:30:26.255+0000] {logging_mixin.py:137} INFO - [2023-05-13T20:30:26.255+0000] {dagbag.py:343} ERROR - Failed to import: /opt/airflow/dags/gw2_dag.py
Traceback (most recent call last):
  File "/home/airflow/.local/lib/python3.7/site-packages/airflow/models/dagbag.py", line 339, in parse
    loader.exec_module(new_module)
  File "<frozen importlib._bootstrap_external>", line 728, in exec_module
  File "<frozen importlib._bootstrap>", line 219, in _call_with_frames_removed
  File "/opt/airflow/dags/gw2_dag.py", line 17, in <module>
    from src import url_writer
ImportError: cannot import name 'url_writer' from 'src' (unknown location)
[2023-05-13T20:30:26.255+0000] {processor.py:755} WARNING - No viable dags retrieved from /opt/airflow/dags/gw2_dag.py
[2023-05-13T20:30:26.267+0000] {processor.py:175} INFO - Processing /opt/airflow/dags/gw2_dag.py took 0.025 seconds
[2023-05-13T20:30:56.656+0000] {processor.py:153} INFO - Started process (PID=5935) to work on /opt/airflow/dags/gw2_dag.py
[2023-05-13T20:30:56.656+0000] {processor.py:743} INFO - Processing file /opt/airflow/dags/gw2_dag.py for tasks to queue
[2023-05-13T20:30:56.657+0000] {logging_mixin.py:137} INFO - [2023-05-13T20:30:56.657+0000] {dagbag.py:538} INFO - Filling up the DagBag from /opt/airflow/dags/gw2_dag.py
[2023-05-13T20:30:56.667+0000] {logging_mixin.py:137} INFO - [2023-05-13T20:30:56.667+0000] {dagbag.py:343} ERROR - Failed to import: /opt/airflow/dags/gw2_dag.py
Traceback (most recent call last):
  File "/home/airflow/.local/lib/python3.7/site-packages/airflow/models/dagbag.py", line 339, in parse
    loader.exec_module(new_module)
  File "<frozen importlib._bootstrap_external>", line 728, in exec_module
  File "<frozen importlib._bootstrap>", line 219, in _call_with_frames_removed
  File "/opt/airflow/dags/gw2_dag.py", line 17, in <module>
    from src import url_writer
ImportError: cannot import name 'url_writer' from 'src' (unknown location)
[2023-05-13T20:30:56.667+0000] {processor.py:755} WARNING - No viable dags retrieved from /opt/airflow/dags/gw2_dag.py
[2023-05-13T20:30:56.679+0000] {processor.py:175} INFO - Processing /opt/airflow/dags/gw2_dag.py took 0.025 seconds
[2023-05-13T20:31:14.751+0000] {processor.py:153} INFO - Started process (PID=5972) to work on /opt/airflow/dags/gw2_dag.py
[2023-05-13T20:31:14.754+0000] {processor.py:743} INFO - Processing file /opt/airflow/dags/gw2_dag.py for tasks to queue
[2023-05-13T20:31:14.754+0000] {logging_mixin.py:137} INFO - [2023-05-13T20:31:14.754+0000] {dagbag.py:538} INFO - Filling up the DagBag from /opt/airflow/dags/gw2_dag.py
[2023-05-13T20:31:14.914+0000] {logging_mixin.py:137} INFO - [2023-05-13T20:31:14.913+0000] {dagbag.py:343} ERROR - Failed to import: /opt/airflow/dags/gw2_dag.py
Traceback (most recent call last):
  File "/home/airflow/.local/lib/python3.7/site-packages/airflow/models/dagbag.py", line 339, in parse
    loader.exec_module(new_module)
  File "<frozen importlib._bootstrap_external>", line 728, in exec_module
  File "<frozen importlib._bootstrap>", line 219, in _call_with_frames_removed
  File "/opt/airflow/dags/gw2_dag.py", line 19, in <module>
    from src.s3_load import s3_loader
ModuleNotFoundError: No module named 'src.s3_load'
[2023-05-13T20:31:14.914+0000] {processor.py:755} WARNING - No viable dags retrieved from /opt/airflow/dags/gw2_dag.py
[2023-05-13T20:31:14.932+0000] {processor.py:175} INFO - Processing /opt/airflow/dags/gw2_dag.py took 0.185 seconds
[2023-05-13T20:31:45.891+0000] {processor.py:153} INFO - Started process (PID=6220) to work on /opt/airflow/dags/gw2_dag.py
[2023-05-13T20:31:45.894+0000] {processor.py:743} INFO - Processing file /opt/airflow/dags/gw2_dag.py for tasks to queue
[2023-05-13T20:31:45.894+0000] {logging_mixin.py:137} INFO - [2023-05-13T20:31:45.894+0000] {dagbag.py:538} INFO - Filling up the DagBag from /opt/airflow/dags/gw2_dag.py
[2023-05-13T20:31:45.963+0000] {logging_mixin.py:137} INFO - [2023-05-13T20:31:45.962+0000] {dagbag.py:343} ERROR - Failed to import: /opt/airflow/dags/gw2_dag.py
Traceback (most recent call last):
  File "/home/airflow/.local/lib/python3.7/site-packages/airflow/models/dagbag.py", line 339, in parse
    loader.exec_module(new_module)
  File "<frozen importlib._bootstrap_external>", line 728, in exec_module
  File "<frozen importlib._bootstrap>", line 219, in _call_with_frames_removed
  File "/opt/airflow/dags/gw2_dag.py", line 19, in <module>
    from src.s3_load import s3_loader
ModuleNotFoundError: No module named 'src.s3_load'
[2023-05-13T20:31:45.964+0000] {processor.py:755} WARNING - No viable dags retrieved from /opt/airflow/dags/gw2_dag.py
[2023-05-13T20:31:45.976+0000] {processor.py:175} INFO - Processing /opt/airflow/dags/gw2_dag.py took 0.087 seconds
[2023-05-13T20:32:06.340+0000] {processor.py:153} INFO - Started process (PID=6436) to work on /opt/airflow/dags/gw2_dag.py
[2023-05-13T20:32:06.341+0000] {processor.py:743} INFO - Processing file /opt/airflow/dags/gw2_dag.py for tasks to queue
[2023-05-13T20:32:06.341+0000] {logging_mixin.py:137} INFO - [2023-05-13T20:32:06.341+0000] {dagbag.py:538} INFO - Filling up the DagBag from /opt/airflow/dags/gw2_dag.py
[2023-05-13T20:32:07.399+0000] {logging_mixin.py:137} INFO - [2023-05-13T20:32:07.397+0000] {dagbag.py:343} ERROR - Failed to import: /opt/airflow/dags/gw2_dag.py
Traceback (most recent call last):
  File "/home/airflow/.local/lib/python3.7/site-packages/airflow/models/dagbag.py", line 339, in parse
    loader.exec_module(new_module)
  File "<frozen importlib._bootstrap_external>", line 728, in exec_module
  File "<frozen importlib._bootstrap>", line 219, in _call_with_frames_removed
  File "/opt/airflow/dags/gw2_dag.py", line 21, in <module>
    from main_etl import gw2_etl
  File "/opt/airflow/src/main_etl.py", line 24, in <module>
    logging.config.fileConfig("../config/logging.conf")
  File "/usr/local/lib/python3.7/logging/config.py", line 71, in fileConfig
    formatters = _create_formatters(cp)
  File "/usr/local/lib/python3.7/logging/config.py", line 104, in _create_formatters
    flist = cp["formatters"]["keys"]
  File "/usr/local/lib/python3.7/configparser.py", line 958, in __getitem__
    raise KeyError(key)
KeyError: 'formatters'
[2023-05-13T20:32:07.399+0000] {processor.py:755} WARNING - No viable dags retrieved from /opt/airflow/dags/gw2_dag.py
[2023-05-13T20:32:07.412+0000] {processor.py:175} INFO - Processing /opt/airflow/dags/gw2_dag.py took 1.073 seconds
[2023-05-13T20:32:38.361+0000] {processor.py:153} INFO - Started process (PID=6684) to work on /opt/airflow/dags/gw2_dag.py
[2023-05-13T20:32:38.364+0000] {processor.py:743} INFO - Processing file /opt/airflow/dags/gw2_dag.py for tasks to queue
[2023-05-13T20:32:38.364+0000] {logging_mixin.py:137} INFO - [2023-05-13T20:32:38.364+0000] {dagbag.py:538} INFO - Filling up the DagBag from /opt/airflow/dags/gw2_dag.py
[2023-05-13T20:32:38.830+0000] {logging_mixin.py:137} INFO - [2023-05-13T20:32:38.829+0000] {dagbag.py:343} ERROR - Failed to import: /opt/airflow/dags/gw2_dag.py
Traceback (most recent call last):
  File "/home/airflow/.local/lib/python3.7/site-packages/airflow/models/dagbag.py", line 339, in parse
    loader.exec_module(new_module)
  File "<frozen importlib._bootstrap_external>", line 728, in exec_module
  File "<frozen importlib._bootstrap>", line 219, in _call_with_frames_removed
  File "/opt/airflow/dags/gw2_dag.py", line 21, in <module>
    from main_etl import gw2_etl
  File "/opt/airflow/src/main_etl.py", line 24, in <module>
    logging.config.fileConfig("../config/logging.conf")
  File "/usr/local/lib/python3.7/logging/config.py", line 71, in fileConfig
    formatters = _create_formatters(cp)
  File "/usr/local/lib/python3.7/logging/config.py", line 104, in _create_formatters
    flist = cp["formatters"]["keys"]
  File "/usr/local/lib/python3.7/configparser.py", line 958, in __getitem__
    raise KeyError(key)
KeyError: 'formatters'
[2023-05-13T20:32:38.831+0000] {processor.py:755} WARNING - No viable dags retrieved from /opt/airflow/dags/gw2_dag.py
[2023-05-13T20:32:38.847+0000] {processor.py:175} INFO - Processing /opt/airflow/dags/gw2_dag.py took 0.488 seconds
[2023-05-13T20:33:03.735+0000] {processor.py:153} INFO - Started process (PID=6917) to work on /opt/airflow/dags/gw2_dag.py
[2023-05-13T20:33:03.736+0000] {processor.py:743} INFO - Processing file /opt/airflow/dags/gw2_dag.py for tasks to queue
[2023-05-13T20:33:03.736+0000] {logging_mixin.py:137} INFO - [2023-05-13T20:33:03.736+0000] {dagbag.py:538} INFO - Filling up the DagBag from /opt/airflow/dags/gw2_dag.py
[2023-05-13T20:33:04.068+0000] {logging_mixin.py:137} INFO - [2023-05-13T20:33:04.067+0000] {dagbag.py:343} ERROR - Failed to import: /opt/airflow/dags/gw2_dag.py
Traceback (most recent call last):
  File "/home/airflow/.local/lib/python3.7/site-packages/airflow/models/dagbag.py", line 339, in parse
    loader.exec_module(new_module)
  File "<frozen importlib._bootstrap_external>", line 728, in exec_module
  File "<frozen importlib._bootstrap>", line 219, in _call_with_frames_removed
  File "/opt/airflow/dags/gw2_dag.py", line 21, in <module>
    from main_etl import gw2_etl
  File "/opt/airflow/src/main_etl.py", line 24, in <module>
    logging.config.fileConfig("../config/logging.conf")
  File "/usr/local/lib/python3.7/logging/config.py", line 71, in fileConfig
    formatters = _create_formatters(cp)
  File "/usr/local/lib/python3.7/logging/config.py", line 104, in _create_formatters
    flist = cp["formatters"]["keys"]
  File "/usr/local/lib/python3.7/configparser.py", line 958, in __getitem__
    raise KeyError(key)
KeyError: 'formatters'
[2023-05-13T20:33:04.068+0000] {processor.py:755} WARNING - No viable dags retrieved from /opt/airflow/dags/gw2_dag.py
[2023-05-13T20:33:04.080+0000] {processor.py:175} INFO - Processing /opt/airflow/dags/gw2_dag.py took 0.346 seconds
[2023-05-13T20:33:16.798+0000] {processor.py:153} INFO - Started process (PID=6939) to work on /opt/airflow/dags/gw2_dag.py
[2023-05-13T20:33:16.801+0000] {processor.py:743} INFO - Processing file /opt/airflow/dags/gw2_dag.py for tasks to queue
[2023-05-13T20:33:16.801+0000] {logging_mixin.py:137} INFO - [2023-05-13T20:33:16.801+0000] {dagbag.py:538} INFO - Filling up the DagBag from /opt/airflow/dags/gw2_dag.py
[2023-05-13T20:33:17.290+0000] {logging_mixin.py:137} INFO - [2023-05-13T20:33:17.289+0000] {dagbag.py:343} ERROR - Failed to import: /opt/airflow/dags/gw2_dag.py
Traceback (most recent call last):
  File "/home/airflow/.local/lib/python3.7/site-packages/airflow/models/dagbag.py", line 339, in parse
    loader.exec_module(new_module)
  File "<frozen importlib._bootstrap_external>", line 728, in exec_module
  File "<frozen importlib._bootstrap>", line 219, in _call_with_frames_removed
  File "/opt/airflow/dags/gw2_dag.py", line 21, in <module>
    from main_etl import gw2_etl
  File "/opt/airflow/src/main_etl.py", line 24, in <module>
    logging.config.fileConfig("../config/logging.conf")
  File "/usr/local/lib/python3.7/logging/config.py", line 71, in fileConfig
    formatters = _create_formatters(cp)
  File "/usr/local/lib/python3.7/logging/config.py", line 104, in _create_formatters
    flist = cp["formatters"]["keys"]
  File "/usr/local/lib/python3.7/configparser.py", line 958, in __getitem__
    raise KeyError(key)
KeyError: 'formatters'
[2023-05-13T20:33:17.291+0000] {processor.py:755} WARNING - No viable dags retrieved from /opt/airflow/dags/gw2_dag.py
[2023-05-13T20:33:17.308+0000] {processor.py:175} INFO - Processing /opt/airflow/dags/gw2_dag.py took 0.512 seconds
[2023-05-13T20:33:22.165+0000] {processor.py:153} INFO - Started process (PID=6961) to work on /opt/airflow/dags/gw2_dag.py
[2023-05-13T20:33:22.166+0000] {processor.py:743} INFO - Processing file /opt/airflow/dags/gw2_dag.py for tasks to queue
[2023-05-13T20:33:22.167+0000] {logging_mixin.py:137} INFO - [2023-05-13T20:33:22.167+0000] {dagbag.py:538} INFO - Filling up the DagBag from /opt/airflow/dags/gw2_dag.py
[2023-05-13T20:33:22.584+0000] {logging_mixin.py:137} INFO - [2023-05-13T20:33:22.583+0000] {dagbag.py:343} ERROR - Failed to import: /opt/airflow/dags/gw2_dag.py
Traceback (most recent call last):
  File "/home/airflow/.local/lib/python3.7/site-packages/airflow/models/dagbag.py", line 339, in parse
    loader.exec_module(new_module)
  File "<frozen importlib._bootstrap_external>", line 728, in exec_module
  File "<frozen importlib._bootstrap>", line 219, in _call_with_frames_removed
  File "/opt/airflow/dags/gw2_dag.py", line 21, in <module>
    from main_etl import gw2_etl
  File "/opt/airflow/src/main_etl.py", line 24, in <module>
    logging.config.fileConfig("../config/logging.conf")
  File "/usr/local/lib/python3.7/logging/config.py", line 71, in fileConfig
    formatters = _create_formatters(cp)
  File "/usr/local/lib/python3.7/logging/config.py", line 104, in _create_formatters
    flist = cp["formatters"]["keys"]
  File "/usr/local/lib/python3.7/configparser.py", line 958, in __getitem__
    raise KeyError(key)
KeyError: 'formatters'
[2023-05-13T20:33:22.584+0000] {processor.py:755} WARNING - No viable dags retrieved from /opt/airflow/dags/gw2_dag.py
[2023-05-13T20:33:22.598+0000] {processor.py:175} INFO - Processing /opt/airflow/dags/gw2_dag.py took 0.435 seconds
[2023-05-13T20:33:28.569+0000] {processor.py:153} INFO - Started process (PID=7162) to work on /opt/airflow/dags/gw2_dag.py
[2023-05-13T20:33:28.569+0000] {processor.py:743} INFO - Processing file /opt/airflow/dags/gw2_dag.py for tasks to queue
[2023-05-13T20:33:28.570+0000] {logging_mixin.py:137} INFO - [2023-05-13T20:33:28.569+0000] {dagbag.py:538} INFO - Filling up the DagBag from /opt/airflow/dags/gw2_dag.py
[2023-05-13T20:33:29.080+0000] {logging_mixin.py:137} INFO - [2023-05-13T20:33:29.078+0000] {dagbag.py:343} ERROR - Failed to import: /opt/airflow/dags/gw2_dag.py
Traceback (most recent call last):
  File "/home/airflow/.local/lib/python3.7/site-packages/airflow/models/dagbag.py", line 339, in parse
    loader.exec_module(new_module)
  File "<frozen importlib._bootstrap_external>", line 728, in exec_module
  File "<frozen importlib._bootstrap>", line 219, in _call_with_frames_removed
  File "/opt/airflow/dags/gw2_dag.py", line 21, in <module>
    from main_etl import gw2_etl
  File "/opt/airflow/src/main_etl.py", line 24, in <module>
    logging.config.fileConfig("../config/logging.conf")
  File "/usr/local/lib/python3.7/logging/config.py", line 71, in fileConfig
    formatters = _create_formatters(cp)
  File "/usr/local/lib/python3.7/logging/config.py", line 104, in _create_formatters
    flist = cp["formatters"]["keys"]
  File "/usr/local/lib/python3.7/configparser.py", line 958, in __getitem__
    raise KeyError(key)
KeyError: 'formatters'
[2023-05-13T20:33:29.080+0000] {processor.py:755} WARNING - No viable dags retrieved from /opt/airflow/dags/gw2_dag.py
[2023-05-13T20:33:29.101+0000] {processor.py:175} INFO - Processing /opt/airflow/dags/gw2_dag.py took 0.535 seconds
[2023-05-13T20:33:59.842+0000] {processor.py:153} INFO - Started process (PID=7411) to work on /opt/airflow/dags/gw2_dag.py
[2023-05-13T20:33:59.845+0000] {processor.py:743} INFO - Processing file /opt/airflow/dags/gw2_dag.py for tasks to queue
[2023-05-13T20:33:59.845+0000] {logging_mixin.py:137} INFO - [2023-05-13T20:33:59.845+0000] {dagbag.py:538} INFO - Filling up the DagBag from /opt/airflow/dags/gw2_dag.py
[2023-05-13T20:34:00.183+0000] {logging_mixin.py:137} INFO - [2023-05-13T20:34:00.182+0000] {dagbag.py:343} ERROR - Failed to import: /opt/airflow/dags/gw2_dag.py
Traceback (most recent call last):
  File "/home/airflow/.local/lib/python3.7/site-packages/airflow/models/dagbag.py", line 339, in parse
    loader.exec_module(new_module)
  File "<frozen importlib._bootstrap_external>", line 728, in exec_module
  File "<frozen importlib._bootstrap>", line 219, in _call_with_frames_removed
  File "/opt/airflow/dags/gw2_dag.py", line 21, in <module>
    from main_etl import gw2_etl
  File "/opt/airflow/src/main_etl.py", line 24, in <module>
    logging.config.fileConfig("../config/logging.conf")
  File "/usr/local/lib/python3.7/logging/config.py", line 71, in fileConfig
    formatters = _create_formatters(cp)
  File "/usr/local/lib/python3.7/logging/config.py", line 104, in _create_formatters
    flist = cp["formatters"]["keys"]
  File "/usr/local/lib/python3.7/configparser.py", line 958, in __getitem__
    raise KeyError(key)
KeyError: 'formatters'
[2023-05-13T20:34:00.184+0000] {processor.py:755} WARNING - No viable dags retrieved from /opt/airflow/dags/gw2_dag.py
[2023-05-13T20:34:00.199+0000] {processor.py:175} INFO - Processing /opt/airflow/dags/gw2_dag.py took 0.359 seconds
[2023-05-13T20:34:31.156+0000] {processor.py:153} INFO - Started process (PID=7644) to work on /opt/airflow/dags/gw2_dag.py
[2023-05-13T20:34:31.159+0000] {processor.py:743} INFO - Processing file /opt/airflow/dags/gw2_dag.py for tasks to queue
[2023-05-13T20:34:31.159+0000] {logging_mixin.py:137} INFO - [2023-05-13T20:34:31.159+0000] {dagbag.py:538} INFO - Filling up the DagBag from /opt/airflow/dags/gw2_dag.py
[2023-05-13T20:34:31.531+0000] {logging_mixin.py:137} INFO - [2023-05-13T20:34:31.530+0000] {dagbag.py:343} ERROR - Failed to import: /opt/airflow/dags/gw2_dag.py
Traceback (most recent call last):
  File "/home/airflow/.local/lib/python3.7/site-packages/airflow/models/dagbag.py", line 339, in parse
    loader.exec_module(new_module)
  File "<frozen importlib._bootstrap_external>", line 728, in exec_module
  File "<frozen importlib._bootstrap>", line 219, in _call_with_frames_removed
  File "/opt/airflow/dags/gw2_dag.py", line 21, in <module>
    from main_etl import gw2_etl
  File "/opt/airflow/src/main_etl.py", line 24, in <module>
    logging.config.fileConfig("../config/logging.conf")
  File "/usr/local/lib/python3.7/logging/config.py", line 71, in fileConfig
    formatters = _create_formatters(cp)
  File "/usr/local/lib/python3.7/logging/config.py", line 104, in _create_formatters
    flist = cp["formatters"]["keys"]
  File "/usr/local/lib/python3.7/configparser.py", line 958, in __getitem__
    raise KeyError(key)
KeyError: 'formatters'
[2023-05-13T20:34:31.532+0000] {processor.py:755} WARNING - No viable dags retrieved from /opt/airflow/dags/gw2_dag.py
[2023-05-13T20:34:31.545+0000] {processor.py:175} INFO - Processing /opt/airflow/dags/gw2_dag.py took 0.391 seconds
[2023-05-13T20:35:02.289+0000] {processor.py:153} INFO - Started process (PID=7894) to work on /opt/airflow/dags/gw2_dag.py
[2023-05-13T20:35:02.290+0000] {processor.py:743} INFO - Processing file /opt/airflow/dags/gw2_dag.py for tasks to queue
[2023-05-13T20:35:02.290+0000] {logging_mixin.py:137} INFO - [2023-05-13T20:35:02.290+0000] {dagbag.py:538} INFO - Filling up the DagBag from /opt/airflow/dags/gw2_dag.py
[2023-05-13T20:35:02.760+0000] {logging_mixin.py:137} INFO - [2023-05-13T20:35:02.759+0000] {dagbag.py:343} ERROR - Failed to import: /opt/airflow/dags/gw2_dag.py
Traceback (most recent call last):
  File "/home/airflow/.local/lib/python3.7/site-packages/airflow/models/dagbag.py", line 339, in parse
    loader.exec_module(new_module)
  File "<frozen importlib._bootstrap_external>", line 728, in exec_module
  File "<frozen importlib._bootstrap>", line 219, in _call_with_frames_removed
  File "/opt/airflow/dags/gw2_dag.py", line 21, in <module>
    from main_etl import gw2_etl
  File "/opt/airflow/src/main_etl.py", line 24, in <module>
    logging.config.fileConfig("../config/logging.conf")
  File "/usr/local/lib/python3.7/logging/config.py", line 71, in fileConfig
    formatters = _create_formatters(cp)
  File "/usr/local/lib/python3.7/logging/config.py", line 104, in _create_formatters
    flist = cp["formatters"]["keys"]
  File "/usr/local/lib/python3.7/configparser.py", line 958, in __getitem__
    raise KeyError(key)
KeyError: 'formatters'
[2023-05-13T20:35:02.760+0000] {processor.py:755} WARNING - No viable dags retrieved from /opt/airflow/dags/gw2_dag.py
[2023-05-13T20:35:02.777+0000] {processor.py:175} INFO - Processing /opt/airflow/dags/gw2_dag.py took 0.491 seconds
[2023-05-13T20:35:33.534+0000] {processor.py:153} INFO - Started process (PID=8143) to work on /opt/airflow/dags/gw2_dag.py
[2023-05-13T20:35:33.535+0000] {processor.py:743} INFO - Processing file /opt/airflow/dags/gw2_dag.py for tasks to queue
[2023-05-13T20:35:33.535+0000] {logging_mixin.py:137} INFO - [2023-05-13T20:35:33.535+0000] {dagbag.py:538} INFO - Filling up the DagBag from /opt/airflow/dags/gw2_dag.py
[2023-05-13T20:35:33.961+0000] {logging_mixin.py:137} INFO - [2023-05-13T20:35:33.960+0000] {dagbag.py:343} ERROR - Failed to import: /opt/airflow/dags/gw2_dag.py
Traceback (most recent call last):
  File "/home/airflow/.local/lib/python3.7/site-packages/airflow/models/dagbag.py", line 339, in parse
    loader.exec_module(new_module)
  File "<frozen importlib._bootstrap_external>", line 728, in exec_module
  File "<frozen importlib._bootstrap>", line 219, in _call_with_frames_removed
  File "/opt/airflow/dags/gw2_dag.py", line 21, in <module>
    from main_etl import gw2_etl
  File "/opt/airflow/src/main_etl.py", line 24, in <module>
    logging.config.fileConfig("../config/logging.conf")
  File "/usr/local/lib/python3.7/logging/config.py", line 71, in fileConfig
    formatters = _create_formatters(cp)
  File "/usr/local/lib/python3.7/logging/config.py", line 104, in _create_formatters
    flist = cp["formatters"]["keys"]
  File "/usr/local/lib/python3.7/configparser.py", line 958, in __getitem__
    raise KeyError(key)
KeyError: 'formatters'
[2023-05-13T20:35:33.961+0000] {processor.py:755} WARNING - No viable dags retrieved from /opt/airflow/dags/gw2_dag.py
[2023-05-13T20:35:33.973+0000] {processor.py:175} INFO - Processing /opt/airflow/dags/gw2_dag.py took 0.441 seconds
[2023-05-13T20:35:47.592+0000] {processor.py:153} INFO - Started process (PID=8165) to work on /opt/airflow/dags/gw2_dag.py
[2023-05-13T20:35:47.593+0000] {processor.py:743} INFO - Processing file /opt/airflow/dags/gw2_dag.py for tasks to queue
[2023-05-13T20:35:47.593+0000] {logging_mixin.py:137} INFO - [2023-05-13T20:35:47.593+0000] {dagbag.py:538} INFO - Filling up the DagBag from /opt/airflow/dags/gw2_dag.py
[2023-05-13T20:35:47.957+0000] {logging_mixin.py:137} INFO - [2023-05-13T20:35:47.956+0000] {dagbag.py:343} ERROR - Failed to import: /opt/airflow/dags/gw2_dag.py
Traceback (most recent call last):
  File "/home/airflow/.local/lib/python3.7/site-packages/airflow/models/dagbag.py", line 339, in parse
    loader.exec_module(new_module)
  File "<frozen importlib._bootstrap_external>", line 728, in exec_module
  File "<frozen importlib._bootstrap>", line 219, in _call_with_frames_removed
  File "/opt/airflow/dags/gw2_dag.py", line 21, in <module>
    from main_etl import gw2_etl
  File "/opt/airflow/src/main_etl.py", line 24, in <module>
    logging.config.fileConfig("../config/logging.conf")
  File "/usr/local/lib/python3.7/logging/config.py", line 71, in fileConfig
    formatters = _create_formatters(cp)
  File "/usr/local/lib/python3.7/logging/config.py", line 104, in _create_formatters
    flist = cp["formatters"]["keys"]
  File "/usr/local/lib/python3.7/configparser.py", line 958, in __getitem__
    raise KeyError(key)
KeyError: 'formatters'
[2023-05-13T20:35:47.958+0000] {processor.py:755} WARNING - No viable dags retrieved from /opt/airflow/dags/gw2_dag.py
[2023-05-13T20:35:47.974+0000] {processor.py:175} INFO - Processing /opt/airflow/dags/gw2_dag.py took 0.383 seconds
[2023-05-13T20:36:18.817+0000] {processor.py:153} INFO - Started process (PID=8398) to work on /opt/airflow/dags/gw2_dag.py
[2023-05-13T20:36:18.820+0000] {processor.py:743} INFO - Processing file /opt/airflow/dags/gw2_dag.py for tasks to queue
[2023-05-13T20:36:18.821+0000] {logging_mixin.py:137} INFO - [2023-05-13T20:36:18.820+0000] {dagbag.py:538} INFO - Filling up the DagBag from /opt/airflow/dags/gw2_dag.py
[2023-05-13T20:36:19.162+0000] {logging_mixin.py:137} INFO - [2023-05-13T20:36:19.161+0000] {dagbag.py:343} ERROR - Failed to import: /opt/airflow/dags/gw2_dag.py
Traceback (most recent call last):
  File "/home/airflow/.local/lib/python3.7/site-packages/airflow/models/dagbag.py", line 339, in parse
    loader.exec_module(new_module)
  File "<frozen importlib._bootstrap_external>", line 728, in exec_module
  File "<frozen importlib._bootstrap>", line 219, in _call_with_frames_removed
  File "/opt/airflow/dags/gw2_dag.py", line 21, in <module>
    from main_etl import gw2_etl
  File "/opt/airflow/src/main_etl.py", line 24, in <module>
    logging.config.fileConfig("../config/logging.conf")
  File "/usr/local/lib/python3.7/logging/config.py", line 71, in fileConfig
    formatters = _create_formatters(cp)
  File "/usr/local/lib/python3.7/logging/config.py", line 104, in _create_formatters
    flist = cp["formatters"]["keys"]
  File "/usr/local/lib/python3.7/configparser.py", line 958, in __getitem__
    raise KeyError(key)
KeyError: 'formatters'
[2023-05-13T20:36:19.163+0000] {processor.py:755} WARNING - No viable dags retrieved from /opt/airflow/dags/gw2_dag.py
[2023-05-13T20:36:19.175+0000] {processor.py:175} INFO - Processing /opt/airflow/dags/gw2_dag.py took 0.360 seconds
[2023-05-13T20:36:49.282+0000] {processor.py:153} INFO - Started process (PID=8647) to work on /opt/airflow/dags/gw2_dag.py
[2023-05-13T20:36:49.285+0000] {processor.py:743} INFO - Processing file /opt/airflow/dags/gw2_dag.py for tasks to queue
[2023-05-13T20:36:49.286+0000] {logging_mixin.py:137} INFO - [2023-05-13T20:36:49.285+0000] {dagbag.py:538} INFO - Filling up the DagBag from /opt/airflow/dags/gw2_dag.py
[2023-05-13T20:36:49.742+0000] {logging_mixin.py:137} INFO - [2023-05-13T20:36:49.740+0000] {dagbag.py:343} ERROR - Failed to import: /opt/airflow/dags/gw2_dag.py
Traceback (most recent call last):
  File "/home/airflow/.local/lib/python3.7/site-packages/airflow/models/dagbag.py", line 339, in parse
    loader.exec_module(new_module)
  File "<frozen importlib._bootstrap_external>", line 728, in exec_module
  File "<frozen importlib._bootstrap>", line 219, in _call_with_frames_removed
  File "/opt/airflow/dags/gw2_dag.py", line 21, in <module>
    from main_etl import gw2_etl
  File "/opt/airflow/src/main_etl.py", line 24, in <module>
    logging.config.fileConfig("../config/logging.conf")
  File "/usr/local/lib/python3.7/logging/config.py", line 71, in fileConfig
    formatters = _create_formatters(cp)
  File "/usr/local/lib/python3.7/logging/config.py", line 104, in _create_formatters
    flist = cp["formatters"]["keys"]
  File "/usr/local/lib/python3.7/configparser.py", line 958, in __getitem__
    raise KeyError(key)
KeyError: 'formatters'
[2023-05-13T20:36:49.742+0000] {processor.py:755} WARNING - No viable dags retrieved from /opt/airflow/dags/gw2_dag.py
[2023-05-13T20:36:49.758+0000] {processor.py:175} INFO - Processing /opt/airflow/dags/gw2_dag.py took 0.478 seconds
[2023-05-13T20:37:20.595+0000] {processor.py:153} INFO - Started process (PID=8896) to work on /opt/airflow/dags/gw2_dag.py
[2023-05-13T20:37:20.595+0000] {processor.py:743} INFO - Processing file /opt/airflow/dags/gw2_dag.py for tasks to queue
[2023-05-13T20:37:20.596+0000] {logging_mixin.py:137} INFO - [2023-05-13T20:37:20.596+0000] {dagbag.py:538} INFO - Filling up the DagBag from /opt/airflow/dags/gw2_dag.py
[2023-05-13T20:37:21.092+0000] {logging_mixin.py:137} INFO - [2023-05-13T20:37:21.091+0000] {dagbag.py:343} ERROR - Failed to import: /opt/airflow/dags/gw2_dag.py
Traceback (most recent call last):
  File "/home/airflow/.local/lib/python3.7/site-packages/airflow/models/dagbag.py", line 339, in parse
    loader.exec_module(new_module)
  File "<frozen importlib._bootstrap_external>", line 728, in exec_module
  File "<frozen importlib._bootstrap>", line 219, in _call_with_frames_removed
  File "/opt/airflow/dags/gw2_dag.py", line 21, in <module>
    from main_etl import gw2_etl
  File "/opt/airflow/src/main_etl.py", line 24, in <module>
    logging.config.fileConfig("../config/logging.conf")
  File "/usr/local/lib/python3.7/logging/config.py", line 71, in fileConfig
    formatters = _create_formatters(cp)
  File "/usr/local/lib/python3.7/logging/config.py", line 104, in _create_formatters
    flist = cp["formatters"]["keys"]
  File "/usr/local/lib/python3.7/configparser.py", line 958, in __getitem__
    raise KeyError(key)
KeyError: 'formatters'
[2023-05-13T20:37:21.093+0000] {processor.py:755} WARNING - No viable dags retrieved from /opt/airflow/dags/gw2_dag.py
[2023-05-13T20:37:21.108+0000] {processor.py:175} INFO - Processing /opt/airflow/dags/gw2_dag.py took 0.515 seconds
[2023-05-13T20:37:51.803+0000] {processor.py:153} INFO - Started process (PID=9130) to work on /opt/airflow/dags/gw2_dag.py
[2023-05-13T20:37:51.805+0000] {processor.py:743} INFO - Processing file /opt/airflow/dags/gw2_dag.py for tasks to queue
[2023-05-13T20:37:51.806+0000] {logging_mixin.py:137} INFO - [2023-05-13T20:37:51.806+0000] {dagbag.py:538} INFO - Filling up the DagBag from /opt/airflow/dags/gw2_dag.py
[2023-05-13T20:37:52.266+0000] {logging_mixin.py:137} INFO - [2023-05-13T20:37:52.264+0000] {dagbag.py:343} ERROR - Failed to import: /opt/airflow/dags/gw2_dag.py
Traceback (most recent call last):
  File "/home/airflow/.local/lib/python3.7/site-packages/airflow/models/dagbag.py", line 339, in parse
    loader.exec_module(new_module)
  File "<frozen importlib._bootstrap_external>", line 728, in exec_module
  File "<frozen importlib._bootstrap>", line 219, in _call_with_frames_removed
  File "/opt/airflow/dags/gw2_dag.py", line 21, in <module>
    from main_etl import gw2_etl
  File "/opt/airflow/src/main_etl.py", line 24, in <module>
    logging.config.fileConfig("../config/logging.conf")
  File "/usr/local/lib/python3.7/logging/config.py", line 71, in fileConfig
    formatters = _create_formatters(cp)
  File "/usr/local/lib/python3.7/logging/config.py", line 104, in _create_formatters
    flist = cp["formatters"]["keys"]
  File "/usr/local/lib/python3.7/configparser.py", line 958, in __getitem__
    raise KeyError(key)
KeyError: 'formatters'
[2023-05-13T20:37:52.266+0000] {processor.py:755} WARNING - No viable dags retrieved from /opt/airflow/dags/gw2_dag.py
[2023-05-13T20:37:52.283+0000] {processor.py:175} INFO - Processing /opt/airflow/dags/gw2_dag.py took 0.483 seconds
[2023-05-13T20:38:22.899+0000] {processor.py:153} INFO - Started process (PID=9379) to work on /opt/airflow/dags/gw2_dag.py
[2023-05-13T20:38:22.902+0000] {processor.py:743} INFO - Processing file /opt/airflow/dags/gw2_dag.py for tasks to queue
[2023-05-13T20:38:22.903+0000] {logging_mixin.py:137} INFO - [2023-05-13T20:38:22.902+0000] {dagbag.py:538} INFO - Filling up the DagBag from /opt/airflow/dags/gw2_dag.py
[2023-05-13T20:38:23.234+0000] {logging_mixin.py:137} INFO - [2023-05-13T20:38:23.233+0000] {dagbag.py:343} ERROR - Failed to import: /opt/airflow/dags/gw2_dag.py
Traceback (most recent call last):
  File "/home/airflow/.local/lib/python3.7/site-packages/airflow/models/dagbag.py", line 339, in parse
    loader.exec_module(new_module)
  File "<frozen importlib._bootstrap_external>", line 728, in exec_module
  File "<frozen importlib._bootstrap>", line 219, in _call_with_frames_removed
  File "/opt/airflow/dags/gw2_dag.py", line 21, in <module>
    from main_etl import gw2_etl
  File "/opt/airflow/src/main_etl.py", line 24, in <module>
    logging.config.fileConfig("../config/logging.conf")
  File "/usr/local/lib/python3.7/logging/config.py", line 71, in fileConfig
    formatters = _create_formatters(cp)
  File "/usr/local/lib/python3.7/logging/config.py", line 104, in _create_formatters
    flist = cp["formatters"]["keys"]
  File "/usr/local/lib/python3.7/configparser.py", line 958, in __getitem__
    raise KeyError(key)
KeyError: 'formatters'
[2023-05-13T20:38:23.234+0000] {processor.py:755} WARNING - No viable dags retrieved from /opt/airflow/dags/gw2_dag.py
[2023-05-13T20:38:23.248+0000] {processor.py:175} INFO - Processing /opt/airflow/dags/gw2_dag.py took 0.350 seconds
[2023-05-13T20:38:53.467+0000] {processor.py:153} INFO - Started process (PID=9612) to work on /opt/airflow/dags/gw2_dag.py
[2023-05-13T20:38:53.467+0000] {processor.py:743} INFO - Processing file /opt/airflow/dags/gw2_dag.py for tasks to queue
[2023-05-13T20:38:53.468+0000] {logging_mixin.py:137} INFO - [2023-05-13T20:38:53.467+0000] {dagbag.py:538} INFO - Filling up the DagBag from /opt/airflow/dags/gw2_dag.py
[2023-05-13T20:38:53.872+0000] {logging_mixin.py:137} INFO - [2023-05-13T20:38:53.871+0000] {dagbag.py:343} ERROR - Failed to import: /opt/airflow/dags/gw2_dag.py
Traceback (most recent call last):
  File "/home/airflow/.local/lib/python3.7/site-packages/airflow/models/dagbag.py", line 339, in parse
    loader.exec_module(new_module)
  File "<frozen importlib._bootstrap_external>", line 728, in exec_module
  File "<frozen importlib._bootstrap>", line 219, in _call_with_frames_removed
  File "/opt/airflow/dags/gw2_dag.py", line 21, in <module>
    from main_etl import gw2_etl
  File "/opt/airflow/src/main_etl.py", line 24, in <module>
    logging.config.fileConfig("../config/logging.conf")
  File "/usr/local/lib/python3.7/logging/config.py", line 71, in fileConfig
    formatters = _create_formatters(cp)
  File "/usr/local/lib/python3.7/logging/config.py", line 104, in _create_formatters
    flist = cp["formatters"]["keys"]
  File "/usr/local/lib/python3.7/configparser.py", line 958, in __getitem__
    raise KeyError(key)
KeyError: 'formatters'
[2023-05-13T20:38:53.873+0000] {processor.py:755} WARNING - No viable dags retrieved from /opt/airflow/dags/gw2_dag.py
[2023-05-13T20:38:53.883+0000] {processor.py:175} INFO - Processing /opt/airflow/dags/gw2_dag.py took 0.419 seconds
[2023-05-13T20:39:24.063+0000] {processor.py:153} INFO - Started process (PID=9862) to work on /opt/airflow/dags/gw2_dag.py
[2023-05-13T20:39:24.063+0000] {processor.py:743} INFO - Processing file /opt/airflow/dags/gw2_dag.py for tasks to queue
[2023-05-13T20:39:24.064+0000] {logging_mixin.py:137} INFO - [2023-05-13T20:39:24.064+0000] {dagbag.py:538} INFO - Filling up the DagBag from /opt/airflow/dags/gw2_dag.py
[2023-05-13T20:39:24.545+0000] {logging_mixin.py:137} INFO - [2023-05-13T20:39:24.544+0000] {dagbag.py:343} ERROR - Failed to import: /opt/airflow/dags/gw2_dag.py
Traceback (most recent call last):
  File "/home/airflow/.local/lib/python3.7/site-packages/airflow/models/dagbag.py", line 339, in parse
    loader.exec_module(new_module)
  File "<frozen importlib._bootstrap_external>", line 728, in exec_module
  File "<frozen importlib._bootstrap>", line 219, in _call_with_frames_removed
  File "/opt/airflow/dags/gw2_dag.py", line 21, in <module>
    from main_etl import gw2_etl
  File "/opt/airflow/src/main_etl.py", line 24, in <module>
    logging.config.fileConfig("../config/logging.conf")
  File "/usr/local/lib/python3.7/logging/config.py", line 71, in fileConfig
    formatters = _create_formatters(cp)
  File "/usr/local/lib/python3.7/logging/config.py", line 104, in _create_formatters
    flist = cp["formatters"]["keys"]
  File "/usr/local/lib/python3.7/configparser.py", line 958, in __getitem__
    raise KeyError(key)
KeyError: 'formatters'
[2023-05-13T20:39:24.546+0000] {processor.py:755} WARNING - No viable dags retrieved from /opt/airflow/dags/gw2_dag.py
[2023-05-13T20:39:24.562+0000] {processor.py:175} INFO - Processing /opt/airflow/dags/gw2_dag.py took 0.502 seconds
[2023-05-13T20:39:55.539+0000] {processor.py:153} INFO - Started process (PID=10112) to work on /opt/airflow/dags/gw2_dag.py
[2023-05-13T20:39:55.540+0000] {processor.py:743} INFO - Processing file /opt/airflow/dags/gw2_dag.py for tasks to queue
[2023-05-13T20:39:55.540+0000] {logging_mixin.py:137} INFO - [2023-05-13T20:39:55.540+0000] {dagbag.py:538} INFO - Filling up the DagBag from /opt/airflow/dags/gw2_dag.py
[2023-05-13T20:39:56.014+0000] {logging_mixin.py:137} INFO - [2023-05-13T20:39:56.012+0000] {dagbag.py:343} ERROR - Failed to import: /opt/airflow/dags/gw2_dag.py
Traceback (most recent call last):
  File "/home/airflow/.local/lib/python3.7/site-packages/airflow/models/dagbag.py", line 339, in parse
    loader.exec_module(new_module)
  File "<frozen importlib._bootstrap_external>", line 728, in exec_module
  File "<frozen importlib._bootstrap>", line 219, in _call_with_frames_removed
  File "/opt/airflow/dags/gw2_dag.py", line 21, in <module>
    from main_etl import gw2_etl
  File "/opt/airflow/src/main_etl.py", line 24, in <module>
    logging.config.fileConfig("../config/logging.conf")
  File "/usr/local/lib/python3.7/logging/config.py", line 71, in fileConfig
    formatters = _create_formatters(cp)
  File "/usr/local/lib/python3.7/logging/config.py", line 104, in _create_formatters
    flist = cp["formatters"]["keys"]
  File "/usr/local/lib/python3.7/configparser.py", line 958, in __getitem__
    raise KeyError(key)
KeyError: 'formatters'
[2023-05-13T20:39:56.014+0000] {processor.py:755} WARNING - No viable dags retrieved from /opt/airflow/dags/gw2_dag.py
[2023-05-13T20:39:56.032+0000] {processor.py:175} INFO - Processing /opt/airflow/dags/gw2_dag.py took 0.495 seconds
[2023-05-13T20:40:26.952+0000] {processor.py:153} INFO - Started process (PID=10346) to work on /opt/airflow/dags/gw2_dag.py
[2023-05-13T20:40:26.955+0000] {processor.py:743} INFO - Processing file /opt/airflow/dags/gw2_dag.py for tasks to queue
[2023-05-13T20:40:26.955+0000] {logging_mixin.py:137} INFO - [2023-05-13T20:40:26.955+0000] {dagbag.py:538} INFO - Filling up the DagBag from /opt/airflow/dags/gw2_dag.py
[2023-05-13T20:40:27.431+0000] {logging_mixin.py:137} INFO - [2023-05-13T20:40:27.429+0000] {dagbag.py:343} ERROR - Failed to import: /opt/airflow/dags/gw2_dag.py
Traceback (most recent call last):
  File "/home/airflow/.local/lib/python3.7/site-packages/airflow/models/dagbag.py", line 339, in parse
    loader.exec_module(new_module)
  File "<frozen importlib._bootstrap_external>", line 728, in exec_module
  File "<frozen importlib._bootstrap>", line 219, in _call_with_frames_removed
  File "/opt/airflow/dags/gw2_dag.py", line 21, in <module>
    from main_etl import gw2_etl
  File "/opt/airflow/src/main_etl.py", line 24, in <module>
    logging.config.fileConfig("../config/logging.conf")
  File "/usr/local/lib/python3.7/logging/config.py", line 71, in fileConfig
    formatters = _create_formatters(cp)
  File "/usr/local/lib/python3.7/logging/config.py", line 104, in _create_formatters
    flist = cp["formatters"]["keys"]
  File "/usr/local/lib/python3.7/configparser.py", line 958, in __getitem__
    raise KeyError(key)
KeyError: 'formatters'
[2023-05-13T20:40:27.431+0000] {processor.py:755} WARNING - No viable dags retrieved from /opt/airflow/dags/gw2_dag.py
[2023-05-13T20:40:27.450+0000] {processor.py:175} INFO - Processing /opt/airflow/dags/gw2_dag.py took 0.501 seconds
[2023-05-13T20:40:57.497+0000] {processor.py:153} INFO - Started process (PID=10595) to work on /opt/airflow/dags/gw2_dag.py
[2023-05-13T20:40:57.497+0000] {processor.py:743} INFO - Processing file /opt/airflow/dags/gw2_dag.py for tasks to queue
[2023-05-13T20:40:57.498+0000] {logging_mixin.py:137} INFO - [2023-05-13T20:40:57.498+0000] {dagbag.py:538} INFO - Filling up the DagBag from /opt/airflow/dags/gw2_dag.py
[2023-05-13T20:40:57.897+0000] {logging_mixin.py:137} INFO - [2023-05-13T20:40:57.896+0000] {dagbag.py:343} ERROR - Failed to import: /opt/airflow/dags/gw2_dag.py
Traceback (most recent call last):
  File "/home/airflow/.local/lib/python3.7/site-packages/airflow/models/dagbag.py", line 339, in parse
    loader.exec_module(new_module)
  File "<frozen importlib._bootstrap_external>", line 728, in exec_module
  File "<frozen importlib._bootstrap>", line 219, in _call_with_frames_removed
  File "/opt/airflow/dags/gw2_dag.py", line 21, in <module>
    from main_etl import gw2_etl
  File "/opt/airflow/src/main_etl.py", line 24, in <module>
    logging.config.fileConfig("../config/logging.conf")
  File "/usr/local/lib/python3.7/logging/config.py", line 71, in fileConfig
    formatters = _create_formatters(cp)
  File "/usr/local/lib/python3.7/logging/config.py", line 104, in _create_formatters
    flist = cp["formatters"]["keys"]
  File "/usr/local/lib/python3.7/configparser.py", line 958, in __getitem__
    raise KeyError(key)
KeyError: 'formatters'
[2023-05-13T20:40:57.897+0000] {processor.py:755} WARNING - No viable dags retrieved from /opt/airflow/dags/gw2_dag.py
[2023-05-13T20:40:57.909+0000] {processor.py:175} INFO - Processing /opt/airflow/dags/gw2_dag.py took 0.415 seconds
[2023-05-13T20:40:58.513+0000] {processor.py:153} INFO - Started process (PID=10601) to work on /opt/airflow/dags/gw2_dag.py
[2023-05-13T20:40:58.513+0000] {processor.py:743} INFO - Processing file /opt/airflow/dags/gw2_dag.py for tasks to queue
[2023-05-13T20:40:58.513+0000] {logging_mixin.py:137} INFO - [2023-05-13T20:40:58.513+0000] {dagbag.py:538} INFO - Filling up the DagBag from /opt/airflow/dags/gw2_dag.py
[2023-05-13T20:40:58.841+0000] {logging_mixin.py:137} INFO - [2023-05-13T20:40:58.840+0000] {dagbag.py:343} ERROR - Failed to import: /opt/airflow/dags/gw2_dag.py
Traceback (most recent call last):
  File "/home/airflow/.local/lib/python3.7/site-packages/airflow/models/dagbag.py", line 339, in parse
    loader.exec_module(new_module)
  File "<frozen importlib._bootstrap_external>", line 728, in exec_module
  File "<frozen importlib._bootstrap>", line 219, in _call_with_frames_removed
  File "/opt/airflow/dags/gw2_dag.py", line 21, in <module>
    from main_etl import gw2_etl
  File "/opt/airflow/src/main_etl.py", line 24, in <module>
    logging.config.fileConfig("../config/logging.conf")
  File "/usr/local/lib/python3.7/logging/config.py", line 71, in fileConfig
    formatters = _create_formatters(cp)
  File "/usr/local/lib/python3.7/logging/config.py", line 104, in _create_formatters
    flist = cp["formatters"]["keys"]
  File "/usr/local/lib/python3.7/configparser.py", line 958, in __getitem__
    raise KeyError(key)
KeyError: 'formatters'
[2023-05-13T20:40:58.841+0000] {processor.py:755} WARNING - No viable dags retrieved from /opt/airflow/dags/gw2_dag.py
[2023-05-13T20:40:58.853+0000] {processor.py:175} INFO - Processing /opt/airflow/dags/gw2_dag.py took 0.342 seconds
[2023-05-13T20:41:01.358+0000] {processor.py:153} INFO - Started process (PID=10667) to work on /opt/airflow/dags/gw2_dag.py
[2023-05-13T20:41:01.360+0000] {processor.py:743} INFO - Processing file /opt/airflow/dags/gw2_dag.py for tasks to queue
[2023-05-13T20:41:01.361+0000] {logging_mixin.py:137} INFO - [2023-05-13T20:41:01.361+0000] {dagbag.py:538} INFO - Filling up the DagBag from /opt/airflow/dags/gw2_dag.py
[2023-05-13T20:41:01.831+0000] {logging_mixin.py:137} INFO - [2023-05-13T20:41:01.829+0000] {dagbag.py:343} ERROR - Failed to import: /opt/airflow/dags/gw2_dag.py
Traceback (most recent call last):
  File "/home/airflow/.local/lib/python3.7/site-packages/airflow/models/dagbag.py", line 339, in parse
    loader.exec_module(new_module)
  File "<frozen importlib._bootstrap_external>", line 728, in exec_module
  File "<frozen importlib._bootstrap>", line 219, in _call_with_frames_removed
  File "/opt/airflow/dags/gw2_dag.py", line 21, in <module>
    from main_etl import gw2_etl
  File "/opt/airflow/src/main_etl.py", line 24, in <module>
    logging.config.fileConfig("../config/logging.conf")
  File "/usr/local/lib/python3.7/logging/config.py", line 71, in fileConfig
    formatters = _create_formatters(cp)
  File "/usr/local/lib/python3.7/logging/config.py", line 104, in _create_formatters
    flist = cp["formatters"]["keys"]
  File "/usr/local/lib/python3.7/configparser.py", line 958, in __getitem__
    raise KeyError(key)
KeyError: 'formatters'
[2023-05-13T20:41:01.831+0000] {processor.py:755} WARNING - No viable dags retrieved from /opt/airflow/dags/gw2_dag.py
[2023-05-13T20:41:01.843+0000] {processor.py:175} INFO - Processing /opt/airflow/dags/gw2_dag.py took 0.487 seconds
[2023-05-13T20:41:32.074+0000] {processor.py:153} INFO - Started process (PID=10917) to work on /opt/airflow/dags/gw2_dag.py
[2023-05-13T20:41:32.075+0000] {processor.py:743} INFO - Processing file /opt/airflow/dags/gw2_dag.py for tasks to queue
[2023-05-13T20:41:32.076+0000] {logging_mixin.py:137} INFO - [2023-05-13T20:41:32.075+0000] {dagbag.py:538} INFO - Filling up the DagBag from /opt/airflow/dags/gw2_dag.py
[2023-05-13T20:41:32.641+0000] {logging_mixin.py:137} INFO - [2023-05-13T20:41:32.640+0000] {dagbag.py:343} ERROR - Failed to import: /opt/airflow/dags/gw2_dag.py
Traceback (most recent call last):
  File "/home/airflow/.local/lib/python3.7/site-packages/airflow/models/dagbag.py", line 339, in parse
    loader.exec_module(new_module)
  File "<frozen importlib._bootstrap_external>", line 728, in exec_module
  File "<frozen importlib._bootstrap>", line 219, in _call_with_frames_removed
  File "/opt/airflow/dags/gw2_dag.py", line 21, in <module>
    from main_etl import gw2_etl
  File "/opt/airflow/src/main_etl.py", line 24, in <module>
    logging.config.fileConfig("../config/logging.conf")
  File "/usr/local/lib/python3.7/logging/config.py", line 71, in fileConfig
    formatters = _create_formatters(cp)
  File "/usr/local/lib/python3.7/logging/config.py", line 104, in _create_formatters
    flist = cp["formatters"]["keys"]
  File "/usr/local/lib/python3.7/configparser.py", line 958, in __getitem__
    raise KeyError(key)
KeyError: 'formatters'
[2023-05-13T20:41:32.641+0000] {processor.py:755} WARNING - No viable dags retrieved from /opt/airflow/dags/gw2_dag.py
[2023-05-13T20:41:32.656+0000] {processor.py:175} INFO - Processing /opt/airflow/dags/gw2_dag.py took 0.585 seconds
[2023-05-13T20:42:02.735+0000] {processor.py:153} INFO - Started process (PID=11168) to work on /opt/airflow/dags/gw2_dag.py
[2023-05-13T20:42:02.744+0000] {processor.py:743} INFO - Processing file /opt/airflow/dags/gw2_dag.py for tasks to queue
[2023-05-13T20:42:02.744+0000] {logging_mixin.py:137} INFO - [2023-05-13T20:42:02.744+0000] {dagbag.py:538} INFO - Filling up the DagBag from /opt/airflow/dags/gw2_dag.py
[2023-05-13T20:42:03.197+0000] {logging_mixin.py:137} INFO - [2023-05-13T20:42:03.196+0000] {dagbag.py:343} ERROR - Failed to import: /opt/airflow/dags/gw2_dag.py
Traceback (most recent call last):
  File "/home/airflow/.local/lib/python3.7/site-packages/airflow/models/dagbag.py", line 339, in parse
    loader.exec_module(new_module)
  File "<frozen importlib._bootstrap_external>", line 728, in exec_module
  File "<frozen importlib._bootstrap>", line 219, in _call_with_frames_removed
  File "/opt/airflow/dags/gw2_dag.py", line 21, in <module>
    from main_etl import gw2_etl
  File "/opt/airflow/src/main_etl.py", line 24, in <module>
    logging.config.fileConfig("../config/logging.conf")
  File "/usr/local/lib/python3.7/logging/config.py", line 71, in fileConfig
    formatters = _create_formatters(cp)
  File "/usr/local/lib/python3.7/logging/config.py", line 104, in _create_formatters
    flist = cp["formatters"]["keys"]
  File "/usr/local/lib/python3.7/configparser.py", line 958, in __getitem__
    raise KeyError(key)
KeyError: 'formatters'
[2023-05-13T20:42:03.197+0000] {processor.py:755} WARNING - No viable dags retrieved from /opt/airflow/dags/gw2_dag.py
[2023-05-13T20:42:03.217+0000] {processor.py:175} INFO - Processing /opt/airflow/dags/gw2_dag.py took 0.484 seconds
[2023-05-13T20:42:33.824+0000] {processor.py:153} INFO - Started process (PID=11417) to work on /opt/airflow/dags/gw2_dag.py
[2023-05-13T20:42:33.824+0000] {processor.py:743} INFO - Processing file /opt/airflow/dags/gw2_dag.py for tasks to queue
[2023-05-13T20:42:33.825+0000] {logging_mixin.py:137} INFO - [2023-05-13T20:42:33.825+0000] {dagbag.py:538} INFO - Filling up the DagBag from /opt/airflow/dags/gw2_dag.py
[2023-05-13T20:42:34.155+0000] {logging_mixin.py:137} INFO - [2023-05-13T20:42:34.154+0000] {dagbag.py:343} ERROR - Failed to import: /opt/airflow/dags/gw2_dag.py
Traceback (most recent call last):
  File "/home/airflow/.local/lib/python3.7/site-packages/airflow/models/dagbag.py", line 339, in parse
    loader.exec_module(new_module)
  File "<frozen importlib._bootstrap_external>", line 728, in exec_module
  File "<frozen importlib._bootstrap>", line 219, in _call_with_frames_removed
  File "/opt/airflow/dags/gw2_dag.py", line 21, in <module>
    from main_etl import gw2_etl
  File "/opt/airflow/src/main_etl.py", line 24, in <module>
    logging.config.fileConfig("../config/logging.conf")
  File "/usr/local/lib/python3.7/logging/config.py", line 71, in fileConfig
    formatters = _create_formatters(cp)
  File "/usr/local/lib/python3.7/logging/config.py", line 104, in _create_formatters
    flist = cp["formatters"]["keys"]
  File "/usr/local/lib/python3.7/configparser.py", line 958, in __getitem__
    raise KeyError(key)
KeyError: 'formatters'
[2023-05-13T20:42:34.155+0000] {processor.py:755} WARNING - No viable dags retrieved from /opt/airflow/dags/gw2_dag.py
[2023-05-13T20:42:34.166+0000] {processor.py:175} INFO - Processing /opt/airflow/dags/gw2_dag.py took 0.344 seconds
[2023-05-13T20:42:55.995+0000] {processor.py:153} INFO - Started process (PID=11570) to work on /opt/airflow/dags/gw2_dag.py
[2023-05-13T20:42:55.996+0000] {processor.py:743} INFO - Processing file /opt/airflow/dags/gw2_dag.py for tasks to queue
[2023-05-13T20:42:55.996+0000] {logging_mixin.py:137} INFO - [2023-05-13T20:42:55.996+0000] {dagbag.py:538} INFO - Filling up the DagBag from /opt/airflow/dags/gw2_dag.py
[2023-05-13T20:42:56.406+0000] {logging_mixin.py:137} INFO - [2023-05-13T20:42:56.405+0000] {dagbag.py:343} ERROR - Failed to import: /opt/airflow/dags/gw2_dag.py
Traceback (most recent call last):
  File "/home/airflow/.local/lib/python3.7/site-packages/airflow/models/dagbag.py", line 339, in parse
    loader.exec_module(new_module)
  File "<frozen importlib._bootstrap_external>", line 728, in exec_module
  File "<frozen importlib._bootstrap>", line 219, in _call_with_frames_removed
  File "/opt/airflow/dags/gw2_dag.py", line 21, in <module>
    from main_etl import gw2_etl
  File "/opt/airflow/src/main_etl.py", line 24, in <module>
    logging.config.fileConfig("../config/logging.conf")
  File "/usr/local/lib/python3.7/logging/config.py", line 71, in fileConfig
    formatters = _create_formatters(cp)
  File "/usr/local/lib/python3.7/logging/config.py", line 104, in _create_formatters
    flist = cp["formatters"]["keys"]
  File "/usr/local/lib/python3.7/configparser.py", line 958, in __getitem__
    raise KeyError(key)
KeyError: 'formatters'
[2023-05-13T20:42:56.407+0000] {processor.py:755} WARNING - No viable dags retrieved from /opt/airflow/dags/gw2_dag.py
[2023-05-13T20:42:56.422+0000] {processor.py:175} INFO - Processing /opt/airflow/dags/gw2_dag.py took 0.430 seconds
[2023-05-13T20:43:09.390+0000] {processor.py:153} INFO - Started process (PID=11787) to work on /opt/airflow/dags/gw2_dag.py
[2023-05-13T20:43:09.391+0000] {processor.py:743} INFO - Processing file /opt/airflow/dags/gw2_dag.py for tasks to queue
[2023-05-13T20:43:09.391+0000] {logging_mixin.py:137} INFO - [2023-05-13T20:43:09.391+0000] {dagbag.py:538} INFO - Filling up the DagBag from /opt/airflow/dags/gw2_dag.py
[2023-05-13T20:43:09.723+0000] {logging_mixin.py:137} INFO - [2023-05-13T20:43:09.722+0000] {dagbag.py:343} ERROR - Failed to import: /opt/airflow/dags/gw2_dag.py
Traceback (most recent call last):
  File "/home/airflow/.local/lib/python3.7/site-packages/airflow/models/dagbag.py", line 339, in parse
    loader.exec_module(new_module)
  File "<frozen importlib._bootstrap_external>", line 728, in exec_module
  File "<frozen importlib._bootstrap>", line 219, in _call_with_frames_removed
  File "/opt/airflow/dags/gw2_dag.py", line 21, in <module>
    from main_etl import gw2_etl
  File "/opt/airflow/src/main_etl.py", line 24, in <module>
    logging.config.fileConfig("../config/logging.conf")
  File "/usr/local/lib/python3.7/logging/config.py", line 71, in fileConfig
    formatters = _create_formatters(cp)
  File "/usr/local/lib/python3.7/logging/config.py", line 104, in _create_formatters
    flist = cp["formatters"]["keys"]
  File "/usr/local/lib/python3.7/configparser.py", line 958, in __getitem__
    raise KeyError(key)
KeyError: 'formatters'
[2023-05-13T20:43:09.724+0000] {processor.py:755} WARNING - No viable dags retrieved from /opt/airflow/dags/gw2_dag.py
[2023-05-13T20:43:09.737+0000] {processor.py:175} INFO - Processing /opt/airflow/dags/gw2_dag.py took 0.348 seconds
[2023-05-13T20:43:16.445+0000] {processor.py:153} INFO - Started process (PID=11793) to work on /opt/airflow/dags/gw2_dag.py
[2023-05-13T20:43:16.447+0000] {processor.py:743} INFO - Processing file /opt/airflow/dags/gw2_dag.py for tasks to queue
[2023-05-13T20:43:16.448+0000] {logging_mixin.py:137} INFO - [2023-05-13T20:43:16.448+0000] {dagbag.py:538} INFO - Filling up the DagBag from /opt/airflow/dags/gw2_dag.py
[2023-05-13T20:43:16.949+0000] {logging_mixin.py:137} INFO - [2023-05-13T20:43:16.948+0000] {dagbag.py:343} ERROR - Failed to import: /opt/airflow/dags/gw2_dag.py
Traceback (most recent call last):
  File "/home/airflow/.local/lib/python3.7/site-packages/airflow/models/dagbag.py", line 339, in parse
    loader.exec_module(new_module)
  File "<frozen importlib._bootstrap_external>", line 728, in exec_module
  File "<frozen importlib._bootstrap>", line 219, in _call_with_frames_removed
  File "/opt/airflow/dags/gw2_dag.py", line 21, in <module>
    from main_etl import gw2_etl
  File "/opt/airflow/src/main_etl.py", line 24, in <module>
    logging.config.fileConfig("../config/logging.conf")
  File "/usr/local/lib/python3.7/logging/config.py", line 71, in fileConfig
    formatters = _create_formatters(cp)
  File "/usr/local/lib/python3.7/logging/config.py", line 104, in _create_formatters
    flist = cp["formatters"]["keys"]
  File "/usr/local/lib/python3.7/configparser.py", line 958, in __getitem__
    raise KeyError(key)
KeyError: 'formatters'
[2023-05-13T20:43:16.950+0000] {processor.py:755} WARNING - No viable dags retrieved from /opt/airflow/dags/gw2_dag.py
[2023-05-13T20:43:16.964+0000] {processor.py:175} INFO - Processing /opt/airflow/dags/gw2_dag.py took 0.522 seconds
[2023-05-13T20:43:47.542+0000] {processor.py:153} INFO - Started process (PID=12042) to work on /opt/airflow/dags/gw2_dag.py
[2023-05-13T20:43:47.545+0000] {processor.py:743} INFO - Processing file /opt/airflow/dags/gw2_dag.py for tasks to queue
[2023-05-13T20:43:47.545+0000] {logging_mixin.py:137} INFO - [2023-05-13T20:43:47.545+0000] {dagbag.py:538} INFO - Filling up the DagBag from /opt/airflow/dags/gw2_dag.py
[2023-05-13T20:43:47.864+0000] {logging_mixin.py:137} INFO - [2023-05-13T20:43:47.863+0000] {dagbag.py:343} ERROR - Failed to import: /opt/airflow/dags/gw2_dag.py
Traceback (most recent call last):
  File "/home/airflow/.local/lib/python3.7/site-packages/airflow/models/dagbag.py", line 339, in parse
    loader.exec_module(new_module)
  File "<frozen importlib._bootstrap_external>", line 728, in exec_module
  File "<frozen importlib._bootstrap>", line 219, in _call_with_frames_removed
  File "/opt/airflow/dags/gw2_dag.py", line 21, in <module>
    from main_etl import gw2_etl
  File "/opt/airflow/src/main_etl.py", line 24, in <module>
    logging.config.fileConfig("../config/logging.conf")
  File "/usr/local/lib/python3.7/logging/config.py", line 71, in fileConfig
    formatters = _create_formatters(cp)
  File "/usr/local/lib/python3.7/logging/config.py", line 104, in _create_formatters
    flist = cp["formatters"]["keys"]
  File "/usr/local/lib/python3.7/configparser.py", line 958, in __getitem__
    raise KeyError(key)
KeyError: 'formatters'
[2023-05-13T20:43:47.864+0000] {processor.py:755} WARNING - No viable dags retrieved from /opt/airflow/dags/gw2_dag.py
[2023-05-13T20:43:47.877+0000] {processor.py:175} INFO - Processing /opt/airflow/dags/gw2_dag.py took 0.336 seconds
[2023-05-13T20:44:18.078+0000] {processor.py:153} INFO - Started process (PID=12275) to work on /opt/airflow/dags/gw2_dag.py
[2023-05-13T20:44:18.081+0000] {processor.py:743} INFO - Processing file /opt/airflow/dags/gw2_dag.py for tasks to queue
[2023-05-13T20:44:18.081+0000] {logging_mixin.py:137} INFO - [2023-05-13T20:44:18.081+0000] {dagbag.py:538} INFO - Filling up the DagBag from /opt/airflow/dags/gw2_dag.py
[2023-05-13T20:44:18.544+0000] {logging_mixin.py:137} INFO - [2023-05-13T20:44:18.542+0000] {dagbag.py:343} ERROR - Failed to import: /opt/airflow/dags/gw2_dag.py
Traceback (most recent call last):
  File "/home/airflow/.local/lib/python3.7/site-packages/airflow/models/dagbag.py", line 339, in parse
    loader.exec_module(new_module)
  File "<frozen importlib._bootstrap_external>", line 728, in exec_module
  File "<frozen importlib._bootstrap>", line 219, in _call_with_frames_removed
  File "/opt/airflow/dags/gw2_dag.py", line 21, in <module>
    from main_etl import gw2_etl
  File "/opt/airflow/src/main_etl.py", line 24, in <module>
    logging.config.fileConfig("../config/logging.conf")
  File "/usr/local/lib/python3.7/logging/config.py", line 71, in fileConfig
    formatters = _create_formatters(cp)
  File "/usr/local/lib/python3.7/logging/config.py", line 104, in _create_formatters
    flist = cp["formatters"]["keys"]
  File "/usr/local/lib/python3.7/configparser.py", line 958, in __getitem__
    raise KeyError(key)
KeyError: 'formatters'
[2023-05-13T20:44:18.544+0000] {processor.py:755} WARNING - No viable dags retrieved from /opt/airflow/dags/gw2_dag.py
[2023-05-13T20:44:18.560+0000] {processor.py:175} INFO - Processing /opt/airflow/dags/gw2_dag.py took 0.484 seconds
[2023-05-13T20:44:49.031+0000] {processor.py:153} INFO - Started process (PID=12524) to work on /opt/airflow/dags/gw2_dag.py
[2023-05-13T20:44:49.033+0000] {processor.py:743} INFO - Processing file /opt/airflow/dags/gw2_dag.py for tasks to queue
[2023-05-13T20:44:49.034+0000] {logging_mixin.py:137} INFO - [2023-05-13T20:44:49.034+0000] {dagbag.py:538} INFO - Filling up the DagBag from /opt/airflow/dags/gw2_dag.py
[2023-05-13T20:44:49.517+0000] {logging_mixin.py:137} INFO - [2023-05-13T20:44:49.516+0000] {dagbag.py:343} ERROR - Failed to import: /opt/airflow/dags/gw2_dag.py
Traceback (most recent call last):
  File "/home/airflow/.local/lib/python3.7/site-packages/airflow/models/dagbag.py", line 339, in parse
    loader.exec_module(new_module)
  File "<frozen importlib._bootstrap_external>", line 728, in exec_module
  File "<frozen importlib._bootstrap>", line 219, in _call_with_frames_removed
  File "/opt/airflow/dags/gw2_dag.py", line 21, in <module>
    from main_etl import gw2_etl
  File "/opt/airflow/src/main_etl.py", line 24, in <module>
    logging.config.fileConfig("../config/logging.conf")
  File "/usr/local/lib/python3.7/logging/config.py", line 71, in fileConfig
    formatters = _create_formatters(cp)
  File "/usr/local/lib/python3.7/logging/config.py", line 104, in _create_formatters
    flist = cp["formatters"]["keys"]
  File "/usr/local/lib/python3.7/configparser.py", line 958, in __getitem__
    raise KeyError(key)
KeyError: 'formatters'
[2023-05-13T20:44:49.518+0000] {processor.py:755} WARNING - No viable dags retrieved from /opt/airflow/dags/gw2_dag.py
[2023-05-13T20:44:49.532+0000] {processor.py:175} INFO - Processing /opt/airflow/dags/gw2_dag.py took 0.504 seconds
[2023-05-13T20:45:19.560+0000] {processor.py:153} INFO - Started process (PID=12756) to work on /opt/airflow/dags/gw2_dag.py
[2023-05-13T20:45:19.561+0000] {processor.py:743} INFO - Processing file /opt/airflow/dags/gw2_dag.py for tasks to queue
[2023-05-13T20:45:19.561+0000] {logging_mixin.py:137} INFO - [2023-05-13T20:45:19.561+0000] {dagbag.py:538} INFO - Filling up the DagBag from /opt/airflow/dags/gw2_dag.py
[2023-05-13T20:45:19.914+0000] {logging_mixin.py:137} INFO - [2023-05-13T20:45:19.913+0000] {dagbag.py:343} ERROR - Failed to import: /opt/airflow/dags/gw2_dag.py
Traceback (most recent call last):
  File "/home/airflow/.local/lib/python3.7/site-packages/airflow/models/dagbag.py", line 339, in parse
    loader.exec_module(new_module)
  File "<frozen importlib._bootstrap_external>", line 728, in exec_module
  File "<frozen importlib._bootstrap>", line 219, in _call_with_frames_removed
  File "/opt/airflow/dags/gw2_dag.py", line 21, in <module>
    from main_etl import gw2_etl
  File "/opt/airflow/src/main_etl.py", line 24, in <module>
    logging.config.fileConfig("../config/logging.conf")
  File "/usr/local/lib/python3.7/logging/config.py", line 71, in fileConfig
    formatters = _create_formatters(cp)
  File "/usr/local/lib/python3.7/logging/config.py", line 104, in _create_formatters
    flist = cp["formatters"]["keys"]
  File "/usr/local/lib/python3.7/configparser.py", line 958, in __getitem__
    raise KeyError(key)
KeyError: 'formatters'
[2023-05-13T20:45:19.915+0000] {processor.py:755} WARNING - No viable dags retrieved from /opt/airflow/dags/gw2_dag.py
[2023-05-13T20:45:19.928+0000] {processor.py:175} INFO - Processing /opt/airflow/dags/gw2_dag.py took 0.371 seconds
[2023-05-13T20:45:50.060+0000] {processor.py:153} INFO - Started process (PID=13007) to work on /opt/airflow/dags/gw2_dag.py
[2023-05-13T20:45:50.063+0000] {processor.py:743} INFO - Processing file /opt/airflow/dags/gw2_dag.py for tasks to queue
[2023-05-13T20:45:50.063+0000] {logging_mixin.py:137} INFO - [2023-05-13T20:45:50.063+0000] {dagbag.py:538} INFO - Filling up the DagBag from /opt/airflow/dags/gw2_dag.py
[2023-05-13T20:45:50.533+0000] {logging_mixin.py:137} INFO - [2023-05-13T20:45:50.532+0000] {dagbag.py:343} ERROR - Failed to import: /opt/airflow/dags/gw2_dag.py
Traceback (most recent call last):
  File "/home/airflow/.local/lib/python3.7/site-packages/airflow/models/dagbag.py", line 339, in parse
    loader.exec_module(new_module)
  File "<frozen importlib._bootstrap_external>", line 728, in exec_module
  File "<frozen importlib._bootstrap>", line 219, in _call_with_frames_removed
  File "/opt/airflow/dags/gw2_dag.py", line 21, in <module>
    from main_etl import gw2_etl
  File "/opt/airflow/src/main_etl.py", line 24, in <module>
    logging.config.fileConfig("../config/logging.conf")
  File "/usr/local/lib/python3.7/logging/config.py", line 71, in fileConfig
    formatters = _create_formatters(cp)
  File "/usr/local/lib/python3.7/logging/config.py", line 104, in _create_formatters
    flist = cp["formatters"]["keys"]
  File "/usr/local/lib/python3.7/configparser.py", line 958, in __getitem__
    raise KeyError(key)
KeyError: 'formatters'
[2023-05-13T20:45:50.533+0000] {processor.py:755} WARNING - No viable dags retrieved from /opt/airflow/dags/gw2_dag.py
[2023-05-13T20:45:50.550+0000] {processor.py:175} INFO - Processing /opt/airflow/dags/gw2_dag.py took 0.492 seconds
[2023-05-13T20:46:21.402+0000] {processor.py:153} INFO - Started process (PID=13257) to work on /opt/airflow/dags/gw2_dag.py
[2023-05-13T20:46:21.403+0000] {processor.py:743} INFO - Processing file /opt/airflow/dags/gw2_dag.py for tasks to queue
[2023-05-13T20:46:21.403+0000] {logging_mixin.py:137} INFO - [2023-05-13T20:46:21.403+0000] {dagbag.py:538} INFO - Filling up the DagBag from /opt/airflow/dags/gw2_dag.py
[2023-05-13T20:46:21.737+0000] {logging_mixin.py:137} INFO - [2023-05-13T20:46:21.736+0000] {dagbag.py:343} ERROR - Failed to import: /opt/airflow/dags/gw2_dag.py
Traceback (most recent call last):
  File "/home/airflow/.local/lib/python3.7/site-packages/airflow/models/dagbag.py", line 339, in parse
    loader.exec_module(new_module)
  File "<frozen importlib._bootstrap_external>", line 728, in exec_module
  File "<frozen importlib._bootstrap>", line 219, in _call_with_frames_removed
  File "/opt/airflow/dags/gw2_dag.py", line 21, in <module>
    from main_etl import gw2_etl
  File "/opt/airflow/src/main_etl.py", line 24, in <module>
    logging.config.fileConfig("../config/logging.conf")
  File "/usr/local/lib/python3.7/logging/config.py", line 71, in fileConfig
    formatters = _create_formatters(cp)
  File "/usr/local/lib/python3.7/logging/config.py", line 104, in _create_formatters
    flist = cp["formatters"]["keys"]
  File "/usr/local/lib/python3.7/configparser.py", line 958, in __getitem__
    raise KeyError(key)
KeyError: 'formatters'
[2023-05-13T20:46:21.738+0000] {processor.py:755} WARNING - No viable dags retrieved from /opt/airflow/dags/gw2_dag.py
[2023-05-13T20:46:21.751+0000] {processor.py:175} INFO - Processing /opt/airflow/dags/gw2_dag.py took 0.350 seconds
[2023-05-13T20:46:52.411+0000] {processor.py:153} INFO - Started process (PID=13490) to work on /opt/airflow/dags/gw2_dag.py
[2023-05-13T20:46:52.414+0000] {processor.py:743} INFO - Processing file /opt/airflow/dags/gw2_dag.py for tasks to queue
[2023-05-13T20:46:52.414+0000] {logging_mixin.py:137} INFO - [2023-05-13T20:46:52.414+0000] {dagbag.py:538} INFO - Filling up the DagBag from /opt/airflow/dags/gw2_dag.py
[2023-05-13T20:46:52.876+0000] {logging_mixin.py:137} INFO - [2023-05-13T20:46:52.874+0000] {dagbag.py:343} ERROR - Failed to import: /opt/airflow/dags/gw2_dag.py
Traceback (most recent call last):
  File "/home/airflow/.local/lib/python3.7/site-packages/airflow/models/dagbag.py", line 339, in parse
    loader.exec_module(new_module)
  File "<frozen importlib._bootstrap_external>", line 728, in exec_module
  File "<frozen importlib._bootstrap>", line 219, in _call_with_frames_removed
  File "/opt/airflow/dags/gw2_dag.py", line 21, in <module>
    from main_etl import gw2_etl
  File "/opt/airflow/src/main_etl.py", line 24, in <module>
    logging.config.fileConfig("../config/logging.conf")
  File "/usr/local/lib/python3.7/logging/config.py", line 71, in fileConfig
    formatters = _create_formatters(cp)
  File "/usr/local/lib/python3.7/logging/config.py", line 104, in _create_formatters
    flist = cp["formatters"]["keys"]
  File "/usr/local/lib/python3.7/configparser.py", line 958, in __getitem__
    raise KeyError(key)
KeyError: 'formatters'
[2023-05-13T20:46:52.876+0000] {processor.py:755} WARNING - No viable dags retrieved from /opt/airflow/dags/gw2_dag.py
[2023-05-13T20:46:52.891+0000] {processor.py:175} INFO - Processing /opt/airflow/dags/gw2_dag.py took 0.482 seconds
[2023-05-13T20:47:23.892+0000] {processor.py:153} INFO - Started process (PID=13739) to work on /opt/airflow/dags/gw2_dag.py
[2023-05-13T20:47:23.894+0000] {processor.py:743} INFO - Processing file /opt/airflow/dags/gw2_dag.py for tasks to queue
[2023-05-13T20:47:23.895+0000] {logging_mixin.py:137} INFO - [2023-05-13T20:47:23.895+0000] {dagbag.py:538} INFO - Filling up the DagBag from /opt/airflow/dags/gw2_dag.py
[2023-05-13T20:47:24.363+0000] {logging_mixin.py:137} INFO - [2023-05-13T20:47:24.361+0000] {dagbag.py:343} ERROR - Failed to import: /opt/airflow/dags/gw2_dag.py
Traceback (most recent call last):
  File "/home/airflow/.local/lib/python3.7/site-packages/airflow/models/dagbag.py", line 339, in parse
    loader.exec_module(new_module)
  File "<frozen importlib._bootstrap_external>", line 728, in exec_module
  File "<frozen importlib._bootstrap>", line 219, in _call_with_frames_removed
  File "/opt/airflow/dags/gw2_dag.py", line 21, in <module>
    from main_etl import gw2_etl
  File "/opt/airflow/src/main_etl.py", line 24, in <module>
    logging.config.fileConfig("../config/logging.conf")
  File "/usr/local/lib/python3.7/logging/config.py", line 71, in fileConfig
    formatters = _create_formatters(cp)
  File "/usr/local/lib/python3.7/logging/config.py", line 104, in _create_formatters
    flist = cp["formatters"]["keys"]
  File "/usr/local/lib/python3.7/configparser.py", line 958, in __getitem__
    raise KeyError(key)
KeyError: 'formatters'
[2023-05-13T20:47:24.363+0000] {processor.py:755} WARNING - No viable dags retrieved from /opt/airflow/dags/gw2_dag.py
[2023-05-13T20:47:24.380+0000] {processor.py:175} INFO - Processing /opt/airflow/dags/gw2_dag.py took 0.490 seconds
[2023-05-13T20:47:54.643+0000] {processor.py:153} INFO - Started process (PID=13972) to work on /opt/airflow/dags/gw2_dag.py
[2023-05-13T20:47:54.646+0000] {processor.py:743} INFO - Processing file /opt/airflow/dags/gw2_dag.py for tasks to queue
[2023-05-13T20:47:54.646+0000] {logging_mixin.py:137} INFO - [2023-05-13T20:47:54.646+0000] {dagbag.py:538} INFO - Filling up the DagBag from /opt/airflow/dags/gw2_dag.py
[2023-05-13T20:47:55.156+0000] {logging_mixin.py:137} INFO - [2023-05-13T20:47:55.155+0000] {dagbag.py:343} ERROR - Failed to import: /opt/airflow/dags/gw2_dag.py
Traceback (most recent call last):
  File "/home/airflow/.local/lib/python3.7/site-packages/airflow/models/dagbag.py", line 339, in parse
    loader.exec_module(new_module)
  File "<frozen importlib._bootstrap_external>", line 728, in exec_module
  File "<frozen importlib._bootstrap>", line 219, in _call_with_frames_removed
  File "/opt/airflow/dags/gw2_dag.py", line 21, in <module>
    from main_etl import gw2_etl
  File "/opt/airflow/src/main_etl.py", line 24, in <module>
    logging.config.fileConfig("../config/logging.conf")
  File "/usr/local/lib/python3.7/logging/config.py", line 71, in fileConfig
    formatters = _create_formatters(cp)
  File "/usr/local/lib/python3.7/logging/config.py", line 104, in _create_formatters
    flist = cp["formatters"]["keys"]
  File "/usr/local/lib/python3.7/configparser.py", line 958, in __getitem__
    raise KeyError(key)
KeyError: 'formatters'
[2023-05-13T20:47:55.157+0000] {processor.py:755} WARNING - No viable dags retrieved from /opt/airflow/dags/gw2_dag.py
[2023-05-13T20:47:55.173+0000] {processor.py:175} INFO - Processing /opt/airflow/dags/gw2_dag.py took 0.533 seconds
